Workbook

Sheet Assumptions
B1: Morrisons LBO Model — CD&R Take-Private (2021)
B3: DEAL OVERVIEW | G3: OPERATING MODEL ASSUMPTIONS
B4: Target | C4: Wm Morrison Supermarkets plc | G4: Revenue Growth — Year 1 | H4: 0.025
B5: Acquirer / Sponsor | C5: Clayton, Dubilier & Rice (CD&R) | G5: Revenue Growth — Year 2 | H5: 0.03
B6: Sector | C6: UK Grocery Retail (Consumer Staples) | G6: Revenue Growth — Year 3 | H6: 0.03
B7: Announcement Date | C7: August 2021 | G7: Revenue Growth — Year 4 | H7: 0.025
B8: Completion Date | C8: October 2021 | G8: Revenue Growth — Year 5 | H8: 0.02
B9: Offer Price (p/share) | C9: 287
B10: Fully Diluted Shares (m) | C10: 2414 | G10: MARGIN ASSUMPTIONS
B11: Pre-Bid Share Price (p) | C11: 178 | G11: EBITDA Margin — Year 1 | H11: 0.062
B12: Premium to Undisturbed Price | C12: 0.61 | G12: EBITDA Margin — Year 2 | H12: 0.065
G13: EBITDA Margin — Year 3 | H13: 0.068
B14: ENTRY VALUATION (£m) | G14: EBITDA Margin — Year 4 | H14: 0.07
B15: Equity Value (Offer) | C15: =C9*C10/100 -> 6928.18 | G15: EBITDA Margin — Year 5 | H15: 0.072
B16: Plus: Net Debt (Pre-Deal) | C16: 2600
B17: Plus: Pension Deficit | C17: 350 | G17: OTHER ASSUMPTIONS
B18: Enterprise Value | C18: =SUM(C15:C17) -> 9878.18 | G18: D&A (% of Revenue) | H18: 0.032
G19: Capex (% of Revenue) | H19: 0.025
B20: LTM FINANCIALS (FY21, £m) | G20: Change in NWC (% of ΔRevenue) | H20: -0.02
B21: Revenue | C21: 17565 | G21: Tax Rate | H21: 0.25
B22: EBITDA | C22: 1078 | G22: Hold Period (Years) | H22: 5
B23: EBITDA Margin | C23: =C22/C21 -> 0.061372047
B24: D&A | C24: 565 | G24: EXIT ASSUMPTIONS
B25: EBIT | C25: =C22-C24 -> 513 | G25: Exit EV/EBITDA Multiple — Base | H25: 8.5
B26: Capex (% of Revenue) | C26: 0.025 | G26: Exit EV/EBITDA Multiple — Upside | H26: 9
B27: Tax Rate | C27: 0.25 | G27: Exit EV/EBITDA Multiple — Downside | H27: 7.5
B29: ENTRY MULTIPLES
B30: EV / LTM Revenue | C30: =C18/C21 -> 0.56237859
B31: EV / LTM EBITDA | C31: =C18/C22 -> 9.1634323

Sheet Sources & Uses
B1: Sources & Uses of Funds (£m)
B3: Sources | C3: £m | D3: % of Total | F3: Uses | G3: £m | H3: % of Total
B4: Senior Secured Term Loan B | C4: 2000 | D4: =C4/C10 -> 0.19364496 | F4: Equity Value (Offer) | G4: =Assumptions!C15 -> 6928.18 | H4: =G4/G10 -> 0.67080357
B5: Senior Secured Notes | C5: 1700 | D5: =C5/C10 -> 0.16459822 | F5: Refinance Existing Net Debt | G5: 2600 | H5: =G5/G10 -> 0.25173845
B6: Senior Unsecured Notes | C6: 1300 | D6: =C6/C10 -> 0.12586922 | F6: Pension Deficit Assumed | G6: 350 | H6: =G6/G10 -> 0.033887868
B7: Preference Shares (Goldman/Ares) | C7: 1300 | D7: =C7/C10 -> 0.12586922 | F7: Transaction Fees (est.) | G7: 250 | H7: =G7/G10 -> 0.02420562
B8: Rollover Equity (Management) | C8: 200 | D8: =C8/C10 -> 0.019364496 | F8: Financing Fees (est.) | G8: 150 | H8: =G8/G10 -> 0.014523372
B9: Sponsor Equity (CD&R) | C9: =G10-SUM(C4:C8) -> 3828.18 | D9: =C9/C10 -> 0.37065388 | F9: Other / Breakage Costs | G9: 50 | H9: =G9/G10 -> 0.004841124
B10: Total Sources | C10: =SUM(C4:C9) -> 10328.18 | D10: =SUM(D4:D9) -> 1 | F10: Total Uses | G10: =SUM(G4:G9) -> 10328.18 | H10: =SUM(H4:H9) -> 1
B12: KEY LEVERAGE METRICS AT ENTRY
B13: Total Debt / EBITDA | C13: =SUM(C4:C7)/Assumptions!C22 -> 5.8441558
B14: Senior Debt / EBITDA | C14: =SUM(C4:C5)/Assumptions!C22 -> 3.432282
B15: Equity / Total Capitalisation | C15: =SUM(C8:C9)/C10 -> 0.39001838

Sheet Operating Model
B1: Operating Model (£m)
C3: LTM (FY21) | D3: Year 1 | E3: Year 2 | F3: Year 3 | G3: Year 4 | H3: Year 5
B4: INCOME STATEMENT
B5: Revenue | C5: =Assumptions!C21 -> 17565 | D5: =C5*(1+Assumptions!H4) -> 18004.125 | E5: =D5*(1+Assumptions!H5) -> 18544.249 | F5: =E5*(1+Assumptions!H6) -> 19100.576 | G5: =F5*(1+Assumptions!H7) -> 19578.091 | H5: =G5*(1+Assumptions!H8) -> 19969.652
B6: Revenue Growth % | C6: n/a | D6: =D5/C5-1 -> 0.025 | E6: =E5/D5-1 -> 0.03 | F6: =F5/E5-1 -> 0.03 | G6: =G5/F5-1 -> 0.025 | H6: =H5/G5-1 -> 0.02
B8: EBITDA | C8: =Assumptions!C22 -> 1078 | D8: =D5*Assumptions!H11 -> 1116.2558 | E8: =E5*Assumptions!H12 -> 1205.3762 | F8: =F5*Assumptions!H13 -> 1298.8392 | G8: =G5*Assumptions!H14 -> 1370.4663 | H8: =H5*Assumptions!H15 -> 1437.815
B9: EBITDA Margin | C9: =C8/C5 -> 0.061372047 | D9: =D8/D5 -> 0.062 | E9: =E8/E5 -> 0.065 | F9: =F8/F5 -> 0.068 | G9: =G8/G5 -> 0.07 | H9: =H8/H5 -> 0.072
B11: Depreciation & Amortisation | C11: =Assumptions!C24 -> 565 | D11: =D5*Assumptions!H18 -> 576.132 | E11: =E5*Assumptions!H18 -> 593.41596 | F11: =F5*Assumptions!H18 -> 611.21844 | G11: =G5*Assumptions!H18 -> 626.4989 | H11: =H5*Assumptions!H18 -> 639.02888
B12: EBIT | C12: =C8-C11 -> 513 | D12: =D8-D11 -> 540.12375 | E12: =E8-E11 -> 611.96021 | F12: =F8-F11 -> 687.62074 | G12: =G8-G11 -> 743.96744 | H12: =H8-H11 -> 798.7861
B13: EBIT Margin | C13: =C12/C5 -> 0.029205807 | D13: =D12/D5 -> 0.03 | E13: =E12/E5 -> 0.033 | F13: =F12/F5 -> 0.036 | G13: =G12/G5 -> 0.038 | H13: =H12/H5 -> 0.04
B15: FREE CASH FLOW
B16: EBITDA | C16: =C8 -> 1078 | D16: =D8 -> 1116.2558 | E16: =E8 -> 1205.3762 | F16: =F8 -> 1298.8392 | G16: =G8 -> 1370.4663 | H16: =H8 -> 1437.815
B17: Less: Cash Taxes on EBT | C17: =-C12*Assumptions!H21 -> -128.25 | D17: =-MAX(0,(D12-'Debt Schedule'!D38))*Assumptions!H21 -> -52.280938 | E17: =-MAX(0,(E12-'Debt Schedule'!E38))*Assumptions!H21 -> -72.261915 | F17: =-MAX(0,(F12-'Debt Schedule'!F38))*Assumptions!H21 -> -93.613017 | G17: =-MAX(0,(G12-'Debt Schedule'!G38))*Assumptions!H21 -> -110.58839 | H17: =-MAX(0,(H12-'Debt Schedule'!H38))*Assumptions!H21 -> -127.55124
B18: Less: Capital Expenditure | C18: =-C5*Assumptions!H19 -> -439.125 | D18: =-D5*Assumptions!H19 -> -450.10312 | E18: =-E5*Assumptions!H19 -> -463.60622 | F18: =-F5*Assumptions!H19 -> -477.51441 | G18: =-G5*Assumptions!H19 -> -489.45227 | H18: =-H5*Assumptions!H19 -> -499.24131
B19: Less: Change in NWC | C19: 0 | D19: =(D5-C5)*Assumptions!H20 -> -8.7825 | E19: =(E5-D5)*Assumptions!H20 -> -10.802475 | F19: =(F5-E5)*Assumptions!H20 -> -11.126549 | G19: =(G5-F5)*Assumptions!H20 -> -9.5502881 | H19: =(H5-G5)*Assumptions!H20 -> -7.8312362
B20: Unlevered Free Cash Flow | D20: =SUM(D16:D19) -> 605.08919 | E20: =SUM(E16:E19) -> 658.70556 | F20: =SUM(F16:F19) -> 716.58521 | G20: =SUM(G16:G19) -> 760.8754 | H20: =SUM(H16:H19) -> 803.19118
B21: UFCF Margin | D21: =D20/D5 -> 0.033608364 | E21: =E20/E5 -> 0.035520747 | F21: =F20/F5 -> 0.037516419 | G21: =G20/G5 -> 0.038863616 | H21: =H20/H5 -> 0.040220589

Sheet Debt Schedule
B1: Debt Schedule & Cash Sweep (£m)
C3: Entry | D3: Year 1 | E3: Year 2 | F3: Year 3 | G3: Year 4 | H3: Year 5
B4: INTEREST RATE ASSUMPTIONS
B5: Term Loan B Rate | C5: 0.055
B6: Senior Secured Notes Rate | C6: 0.065
B7: Senior Unsecured Notes Rate | C7: 0.085
B8: Preference Share Coupon (PIK) | C8: 0.1
B10: MANDATORY AMORTISATION (% p.a.)
B11: Term Loan B Amortisation | C11: 0.01
B12: Cash Sweep (% of Excess Cash) | C12: 0.5
B14: SENIOR SECURED TERM LOAN B
B15: Beginning Balance | C15: ='Sources & Uses'!C4 -> 2000 | D15: =C15 -> 2000 | E15: =D18 -> 1852.9554 | F15: =E18 -> 1675.7941 | G15: =F18 -> 1465.7069 | H15: =G18 -> 1228.7476
B16: Mandatory Amortisation | C16: 0 | D16: =-D15*$C$11 -> -20 | E16: =-E15*$C$11 -> -18.529554 | F16: =-F15*$C$11 -> -16.757941 | G16: =-G15*$C$11 -> -14.657069 | H16: =-H15*$C$11 -> -12.287476
B17: Cash Sweep | C17: 0 | D17: =-MIN(D15+D16,MAX(0,D45*$C$12)) -> -127.04459 | E17: =-MIN(E15+E16,MAX(0,E45*$C$12)) -> -158.63173 | F17: =-MIN(F15+F16,MAX(0,F45*$C$12)) -> -193.3293 | G17: =-MIN(G15+G16,MAX(0,G45*$C$12)) -> -222.30223 | H17: =-MIN(H15+H16,MAX(0,H45*$C$12)) -> -251.16129
B18: Ending Balance | C18: =C15 -> 2000 | D18: =MAX(0,D15+D16+D17) -> 1852.9554 | E18: =MAX(0,E15+E16+E17) -> 1675.7941 | F18: =MAX(0,F15+F16+F17) -> 1465.7069 | G18: =MAX(0,G15+G16+G17) -> 1228.7476 | H18: =MAX(0,H15+H16+H17) -> 965.29882
B19: Interest Expense | C19: 0 | D19: =D15*$C$5 -> 110 | E19: =E15*$C$5 -> 101.91255 | F19: =F15*$C$5 -> 92.168677 | G19: =G15*$C$5 -> 80.613879 | H19: =H15*$C$5 -> 67.581118
B21: SENIOR SECURED NOTES
B22: Beginning Balance | C22: ='Sources & Uses'!C5 -> 1700 | D22: =C22 -> 1700 | E22: =D22 -> 1700 | F22: =E22 -> 1700 | G22: =F22 -> 1700 | H22: =G22 -> 1700
B23: Ending Balance | C23: =C22 -> 1700 | D23: =D22 -> 1700 | E23: =E22 -> 1700 | F23: =F22 -> 1700 | G23: =G22 -> 1700 | H23: =H22 -> 1700
B24: Interest Expense | C24: 0 | D24: =D22*$C$6 -> 110.5 | E24: =E22*$C$6 -> 110.5 | F24: =F22*$C$6 -> 110.5 | G24: =G22*$C$6 -> 110.5 | H24: =H22*$C$6 -> 110.5
B26: SENIOR UNSECURED NOTES
B27: Beginning Balance | C27: ='Sources & Uses'!C6 -> 1300 | D27: =C27 -> 1300 | E27: =D27 -> 1300 | F27: =E27 -> 1300 | G27: =F27 -> 1300 | H27: =G27 -> 1300
B28: Ending Balance | C28: =C27 -> 1300 | D28: =D27 -> 1300 | E28: =E27 -> 1300 | F28: =F27 -> 1300 | G28: =G27 -> 1300 | H28: =H27 -> 1300
B29: Interest Expense | C29: 0 | D29: =D27*$C$7 -> 110.5 | E29: =E27*$C$7 -> 110.5 | F29: =F27*$C$7 -> 110.5 | G29: =G27*$C$7 -> 110.5 | H29: =H27*$C$7 -> 110.5
B31: PREFERENCE SHARES (PIK)
B32: Beginning Balance | C32: ='Sources & Uses'!C7 -> 1300 | D32: =C32 -> 1300 | E32: =D34 -> 1430 | F32: =E34 -> 1573 | G32: =F34 -> 1730.3 | H32: =G34 -> 1903.33
B33: PIK Interest Accrual | C33: 0 | D33: =D32*$C$8 -> 130 | E33: =E32*$C$8 -> 143 | F33: =F32*$C$8 -> 157.3 | G33: =G32*$C$8 -> 173.03 | H33: =H32*$C$8 -> 190.333
B34: Ending Balance | C34: =C32 -> 1300 | D34: =D32+D33 -> 1430 | E34: =E32+E33 -> 1573 | F34: =F32+F33 -> 1730.3 | G34: =G32+G33 -> 1903.33 | H34: =H32+H33 -> 2093.663
B36: TOTAL DEBT SUMMARY
B37: Total Debt (EOP) | C37: =C15+C23+C28+C34 -> 6300 | D37: =D18+D23+D28+D34 -> 6282.9554 | E37: =E18+E23+E28+E34 -> 6248.7941 | F37: =F18+F23+F28+F34 -> 6196.0069 | G37: =G18+G23+G28+G34 -> 6132.0776 | H37: =H18+H23+H28+H34 -> 6058.9618
B38: Total Cash Interest | C38: 0 | D38: =D19+D24+D29 -> 331 | E38: =E19+E24+E29 -> 322.91255 | F38: =F19+F24+F29 -> 313.16868 | G38: =G19+G24+G29 -> 301.61388 | H38: =H19+H24+H29 -> 288.58112
B39: Total Debt / EBITDA | D39: =IFERROR(D37/'Operating Model'!D8,0) -> 5.6285985 | E39: =IFERROR(E37/'Operating Model'!E8,0) -> 5.1841029 | F39: =IFERROR(F37/'Operating Model'!F8,0) -> 4.7704188 | G39: =IFERROR(G37/'Operating Model'!G8,0) -> 4.474446 | H39: =IFERROR(H37/'Operating Model'!H8,0) -> 4.2140066
B41: LEVERED FREE CASH FLOW
B42: Unlevered Free Cash Flow | D42: ='Operating Model'!D20 -> 605.08919 | E42: ='Operating Model'!E20 -> 658.70556 | F42: ='Operating Model'!F20 -> 716.58521 | G42: ='Operating Model'!G20 -> 760.8754 | H42: ='Operating Model'!H20 -> 803.19118
B43: Less: Cash Interest | D43: =-D38 -> -331 | E43: =-E38 -> -322.91255 | F43: =-F38 -> -313.16868 | G43: =-G38 -> -301.61388 | H43: =-H38 -> -288.58112
B44: Less: Mandatory Amortisation | D44: =D16 -> -20 | E44: =E16 -> -18.529554 | F44: =F16 -> -16.757941 | G44: =G16 -> -14.657069 | H44: =H16 -> -12.287476
B45: Excess Cash Flow (Pre-Sweep) | D45: =SUM(D42:D44) -> 254.08919 | E45: =SUM(E42:E44) -> 317.26346 | F45: =SUM(F42:F44) -> 386.65859 | G45: =SUM(G42:G44) -> 444.60445 | H45: =SUM(H42:H44) -> 502.32259
B47: CREDIT METRICS
B48: Interest Coverage (EBITDA / Cash Int) | D48: =IFERROR('Operating Model'!D8/D38,0) -> 3.3723739 | E48: =IFERROR('Operating Model'!E8/E38,0) -> 3.7328254 | F48: =IFERROR('Operating Model'!F8/F38,0) -> 4.1474109 | G48: =IFERROR('Operating Model'!G8/G38,0) -> 4.5437775 | H48: =IFERROR('Operating Model'!H8/H38,0) -> 4.9823599
B49: Fixed Charge Coverage | D49: =IFERROR(('Operating Model'!D8+'Operating Model'!D18)/(D38-D16),0) -> 1.8978707 | E49: =IFERROR(('Operating Model'!E8+'Operating Model'!E18)/(E38-E16),0) -> 2.1724619 | F49: =IFERROR(('Operating Model'!F8+'Operating Model'!F18)/(F38-F16),0) -> 2.4894165 | G49: =IFERROR(('Operating Model'!G8+'Operating Model'!G18)/(G38-G16),0) -> 2.7856308 | H49: =IFERROR(('Operating Model'!H8+'Operating Model'!H18)/(H38-H16),0) -> 3.1195468
...

Sheet Returns
B1: Returns Analysis
B3: EXIT VALUATION (£m)
C4: Downside | D4: Base | E4: Upside
B5: Exit EBITDA (Year 5) | C5: ='Operating Model'!H8 -> 1437.815 | D5: ='Operating Model'!H8 -> 1437.815 | E5: ='Operating Model'!H8 -> 1437.815
B6: Exit EV/EBITDA Multiple | C6: =Assumptions!H27 -> 7.5 | D6: =Assumptions!H25 -> 8.5 | E6: =Assumptions!H26 -> 9
B7: Exit Enterprise Value | C7: =C5*C6 -> 10783.612 | D7: =D5*D6 -> 12221.427 | E7: =E5*E6 -> 12940.335
B8: Less: Total Debt at Exit | C8: =-'Debt Schedule'!H37 -> -6058.9618 | D8: =-'Debt Schedule'!H37 -> -6058.9618 | E8: =-'Debt Schedule'!H37 -> -6058.9618
B9: Exit Equity Value | C9: =C7+C8 -> 4724.6505 | D9: =D7+D8 -> 6162.4655 | E9: =E7+E8 -> 6881.373
B11: RETURNS TO SPONSOR
C12: Downside | D12: Base | E12: Upside
B13: Initial Equity Investment | C13: ='Sources & Uses'!C9+'Sources & Uses'!C8 -> 4028.18 | D13: ='Sources & Uses'!C9+'Sources & Uses'!C8 -> 4028.18 | E13: ='Sources & Uses'!C9+'Sources & Uses'!C8 -> 4028.18
B14: Exit Equity Value | C14: =C9 -> 4724.6505 | D14: =D9 -> 6162.4655 | E14: =E9 -> 6881.373
B15: Multiple of Money (MoM) | C15: =C14/C13 -> 1.1728995 | D15: =D14/D13 -> 1.5298387 | E15: =E14/E13 -> 1.7083082
B16: IRR (5-Year Hold) | C16: =C32 -> 0.032409908 | D16: =D32 -> 0.088752401 | E16: =E32 -> 0.11304634
B18: VALUE CREATION BRIDGE (BASE CASE, £m)
B19: Entry Equity | C19: =D13 -> 4028.18
B20: (+) EBITDA Growth Effect | C20: =(D5-Assumptions!C22)*D6 -> 3058.4273
B21: (+) Multiple Expansion / (Contraction) | C21: =Assumptions!C22*(D6-Assumptions!C31) -> -715.18
B22: (+) Debt Paydown | C22: ='Debt Schedule'!C37-'Debt Schedule'!H37 -> 241.03818
B23: (+/-) Cross-Effects & Fees | C23: =D9-SUM(C19:C22) -> -450
B24: Exit Equity (Reconciled) | C24: =SUM(C19:C23) -> 6162.4655
B25: Check vs. Actual (should = 0) | C25: =C24-D9 -> 0
B27: IRR CASH FLOW SCHEDULE
C28: Year 0 | D28: Year 1 | E28: Year 2 | F28: Year 3 | G28: Year 4 | H28: Year 5
B29: Downside Case | C29: =-C13 -> -4028.18 | D29: 0 | E29: 0 | F29: 0 | G29: 0 | H29: =C9 -> 4724.6505
B30: Base Case | C30: =-D13 -> -4028.18 | D30: 0 | E30: 0 | F30: 0 | G30: 0 | H30: =D9 -> 6162.4655
B31: Upside Case | C31: =-E13 -> -4028.18 | D31: 0 | E31: 0 | F31: 0 | G31: 0 | H31: =E9 -> 6881.373
B32: IRR (Proper) | C32: =IFERROR(IRR(C29:H29),0) -> 0.032409908 | D32: =IFERROR(IRR(C30:H30),0) -> 0.088752401 | E32: =IFERROR(IRR(C31:H31),0) -> 0.11304634

Sheet Sensitivity
B1: Sensitivity Analysis
B3: IRR SENSITIVITY: Exit Multiple vs. Year 5 EBITDA Margin
B4: Yr5 EBITDA Margin ↓ | C4: 7 | D4: 7.5 | E4: 8 | F4: 8.5 | G4: 9 | H4: 9.5 | I4: 10
B5: 0.06 | C5: =IFERROR((('Operating Model'!H5*$B5*C$4-'Debt Schedule'!H37)/('Sources & Uses'!C9+'Sources & Uses'!C8))^(1/5)-1,0) -> -0.10383965 | D5: =IFERROR((('Operating Model'!H5*$B5*D$4-'Debt Schedule'!H37)/('Sources & Uses'!C9+'Sources & Uses'!C8))^(1/5)-1,0) -> -0.061846077 | E5: =IFERROR((('Operating Model'!H5*$B5*E$4-'Debt Schedule'!H37)/('Sources & Uses'!C9+'Sources & Uses'!C8))^(1/5)-1,0) -> -0.026252629 | F5: =IFERROR((('Operating Model'!H5*$B5*F$4-'Debt Schedule'!H37)/('Sources & Uses'!C9+'Sources & Uses'!C8))^(1/5)-1,0) -> 0.0047888963 | G5: =IFERROR((('Operating Model'!H5*$B5*G$4-'Debt Schedule'!H37)/('Sources & Uses'!C9+'Sources & Uses'!C8))^(1/5)-1,0) -> 0.032409908 | H5: =IFERROR((('Operating Model'!H5*$B5*H$4-'Debt Schedule'!H37)/('Sources & Uses'!C9+'Sources & Uses'!C8))^(1/5)-1,0) -> 0.057356878 | I5: =IFERROR((('Operating Model'!H5*$B5*I$4-'Debt Schedule'!H37)/('Sources & Uses'!C9+'Sources & Uses'!C8))^(1/5)-1,0) -> 0.080150011
B6: 0.065 | C6: =IFERROR((('Operating Model'!H5*$B6*C$4-'Debt Schedule'!H37)/('Sources & Uses'!C9+'Sources & Uses'!C8))^(1/5)-1,0) -> -0.055531863 | D6: =IFERROR((('Operating Model'!H5*$B6*D$4-'Debt Schedule'!H37)/('Sources & Uses'!C9+'Sources & Uses'!C8))^(1/5)-1,0) -> -0.018118481 | E6: =IFERROR((('Operating Model'!H5*$B6*E$4-'Debt Schedule'!H37)/('Sources & Uses'!C9+'Sources & Uses'!C8))^(1/5)-1,0) -> 0.014333149 | F6: =IFERROR((('Operating Model'!H5*$B6*F$4-'Debt Schedule'!H37)/('Sources & Uses'!C9+'Sources & Uses'!C8))^(1/5)-1,0) -> 0.043095609 | G6: =IFERROR((('Operating Model'!H5*$B6*G$4-'Debt Schedule'!H37)/('Sources & Uses'!C9+'Sources & Uses'!C8))^(1/5)-1,0) -> 0.068996401 | H6: =IFERROR((('Operating Model'!H5*$B6*H$4-'Debt Schedule'!H37)/('Sources & Uses'!C9+'Sources & Uses'!C8))^(1/5)-1,0) -> 0.092605974 | I6: =IFERROR((('Operating Model'!H5*$B6*I$4-'Debt Schedule'!H37)/('Sources & Uses'!C9+'Sources & Uses'!C8))^(1/5)-1,0) -> 0.11433537
B7: 0.068 | C7: =IFERROR((('Operating Model'!H5*$B7*C$4-'Debt Schedule'!H37)/('Sources & Uses'!C9+'Sources & Uses'!C8))^(1/5)-1,0) -> -0.030704448 | D7: =IFERROR((('Operating Model'!H5*$B7*D$4-'Debt Schedule'!H37)/('Sources & Uses'!C9+'Sources & Uses'!C8))^(1/5)-1,0) -> 0.0047888963 | E7: =IFERROR((('Operating Model'!H5*$B7*E$4-'Debt Schedule'!H37)/('Sources & Uses'!C9+'Sources & Uses'!C8))^(1/5)-1,0) -> 0.035877481 | F7: =IFERROR((('Operating Model'!H5*$B7*F$4-'Debt Schedule'!H37)/('Sources & Uses'!C9+'Sources & Uses'!C8))^(1/5)-1,0) -> 0.063627978 | G7: =IFERROR((('Operating Model'!H5*$B7*G$4-'Debt Schedule'!H37)/('Sources & Uses'!C9+'Sources & Uses'!C8))^(1/5)-1,0) -> 0.088752401 | H7: =IFERROR((('Operating Model'!H5*$B7*H$4-'Debt Schedule'!H37)/('Sources & Uses'!C9+'Sources & Uses'!C8))^(1/5)-1,0) -> 0.11175131 | I7: =IFERROR((('Operating Model'!H5*$B7*I$4-'Debt Schedule'!H37)/('Sources & Uses'!C9+'Sources & Uses'!C8))^(1/5)-1,0) -> 0.13299094
B8: 0.07 | C8: =IFERROR((('Operating Model'!H5*$B8*C$4-'Debt Schedule'!H37)/('Sources & Uses'!C9+'Sources & Uses'!C8))^(1/5)-1,0) -> -0.015466021 | D8: =IFERROR((('Operating Model'!H5*$B8*D$4-'Debt Schedule'!H37)/('Sources & Uses'!C9+'Sources & Uses'!C8))^(1/5)-1,0) -> 0.018973656 | E8: =IFERROR((('Operating Model'!H5*$B8*E$4-'Debt Schedule'!H37)/('Sources & Uses'!C9+'Sources & Uses'!C8))^(1/5)-1,0) -> 0.049302696 | F8: =IFERROR((('Operating Model'!H5*$B8*F$4-'Debt Schedule'!H37)/('Sources & Uses'!C9+'Sources & Uses'!C8))^(1/5)-1,0) -> 0.076483324 | G8: =IFERROR((('Operating Model'!H5*$B8*G$4-'Debt Schedule'!H37)/('Sources & Uses'!C9+'Sources & Uses'!C8))^(1/5)-1,0) -> 0.10116731 | H8: =IFERROR((('Operating Model'!H5*$B8*H$4-'Debt Schedule'!H37)/('Sources & Uses'!C9+'Sources & Uses'!C8))^(1/5)-1,0) -> 0.12381798 | I8: =IFERROR((('Operating Model'!H5*$B8*I$4-'Debt Schedule'!H37)/('Sources & Uses'!C9+'Sources & Uses'!C8))^(1/5)-1,0) -> 0.14477731
B9: 0.072 | C9: =IFERROR((('Operating Model'!H5*$B9*C$4-'Debt Schedule'!H37)/('Sources & Uses'!C9+'Sources & Uses'!C8))^(1/5)-1,0) -> -0.001116492 | D9: =IFERROR((('Operating Model'!H5*$B9*D$4-'Debt Schedule'!H37)/('Sources & Uses'!C9+'Sources & Uses'!C8))^(1/5)-1,0) -> 0.032409908 | E9: =IFERROR((('Operating Model'!H5*$B9*E$4-'Debt Schedule'!H37)/('Sources & Uses'!C9+'Sources & Uses'!C8))^(1/5)-1,0) -> 0.062074048 | F9: =IFERROR((('Operating Model'!H5*$B9*F$4-'Debt Schedule'!H37)/('Sources & Uses'!C9+'Sources & Uses'!C8))^(1/5)-1,0) -> 0.088752401 | G9: =IFERROR((('Operating Model'!H5*$B9*G$4-'Debt Schedule'!H37)/('Sources & Uses'!C9+'Sources & Uses'!C8))^(1/5)-1,0) -> 0.11304634 | H9: =IFERROR((('Operating Model'!H5*$B9*H$4-'Debt Schedule'!H37)/('Sources & Uses'!C9+'Sources & Uses'!C8))^(1/5)-1,0) -> 0.13538761 | I9: =IFERROR((('Operating Model'!H5*$B9*I$4-'Debt Schedule'!H37)/('Sources & Uses'!C9+'Sources & Uses'!C8))^(1/5)-1,0) -> 0.15609737
B10: 0.075 | C10: =IFERROR((('Operating Model'!H5*$B10*C$4-'Debt Schedule'!H37)/('Sources & Uses'!C9+'Sources & Uses'!C8))^(1/5)-1,0) -> 0.018973656 | D10: =IFERROR((('Operating Model'!H5*$B10*D$4-'Debt Schedule'!H37)/('Sources & Uses'!C9+'Sources & Uses'!C8))^(1/5)-1,0) -> 0.051339468 | E10: =IFERROR((('Operating Model'!H5*$B10*E$4-'Debt Schedule'!H37)/('Sources & Uses'!C9+'Sources & Uses'!C8))^(1/5)-1,0) -> 0.080150011 | F10: =IFERROR((('Operating Model'!H5*$B10*F$4-'Debt Schedule'!H37)/('Sources & Uses'!C9+'Sources & Uses'!C8))^(1/5)-1,0) -> 0.10617902 | G10: =IFERROR((('Operating Model'!H5*$B10*G$4-'Debt Schedule'!H37)/('Sources & Uses'!C9+'Sources & Uses'!C8))^(1/5)-1,0) -> 0.12996629 | H10: =IFERROR((('Operating Model'!H5*$B10*H$4-'Debt Schedule'!H37)/('Sources & Uses'!C9+'Sources & Uses'!C8))^(1/5)-1,0) -> 0.15190436 | I10: =IFERROR((('Operating Model'!H5*$B10*I$4-'Debt Schedule'!H37)/('Sources & Uses'!C9+'Sources & Uses'!C8))^(1/5)-1,0) -> 0.17228828
B11: 0.08 | C11: =IFERROR((('Operating Model'!H5*$B11*C$4-'Debt Schedule'!H37)/('Sources & Uses'!C9+'Sources & Uses'!C8))^(1/5)-1,0) -> 0.049302696 | D11: =IFERROR((('Operating Model'!H5*$B11*D$4-'Debt Schedule'!H37)/('Sources & Uses'!C9+'Sources & Uses'!C8))^(1/5)-1,0) -> 0.080150011 | E11: =IFERROR((('Operating Model'!H5*$B11*E$4-'Debt Schedule'!H37)/('Sources & Uses'!C9+'Sources & Uses'!C8))^(1/5)-1,0) -> 0.10782959 | F11: =IFERROR((('Operating Model'!H5*$B11*F$4-'Debt Schedule'!H37)/('Sources & Uses'!C9+'Sources & Uses'!C8))^(1/5)-1,0) -> 0.13299094 | G11: =IFERROR((('Operating Model'!H5*$B11*G$4-'Debt Schedule'!H37)/('Sources & Uses'!C9+'Sources & Uses'!C8))^(1/5)-1,0) -> 0.15609737 | H11: =IFERROR((('Operating Model'!H5*$B11*H$4-'Debt Schedule'!H37)/('Sources & Uses'!C9+'Sources & Uses'!C8))^(1/5)-1,0) -> 0.17749181 | I11: =IFERROR((('Operating Model'!H5*$B11*I$4-'Debt Schedule'!H37)/('Sources & Uses'!C9+'Sources & Uses'!C8))^(1/5)-1,0) -> 0.19743566
B14: MoM SENSITIVITY: Exit Multiple vs. Entry Leverage (Debt/EBITDA)
B15: Entry Leverage ↓ | C15: 7 | D15: 7.5 | E15: 8 | F15: 8.5 | G15: 9 | H15: 9.5 | I15: 10
B16: 4 | C16: =IFERROR(('Operating Model'!H8*C$15-'Debt Schedule'!H37)/(Assumptions!C18-Assumptions!C22*$B16),0) -> 0.71965747 | D16: =IFERROR(('Operating Model'!H8*D$15-'Debt Schedule'!H37)/(Assumptions!C18-Assumptions!C22*$B16),0) -> 0.84881382 | E16: =IFERROR(('Operating Model'!H8*E$15-'Debt Schedule'!H37)/(Assumptions!C18-Assumptions!C22*$B16),0) -> 0.97797017 | F16: =IFERROR(('Operating Model'!H8*F$15-'Debt Schedule'!H37)/(Assumptions!C18-Assumptions!C22*$B16),0) -> 1.1071265 | G16: =IFERROR(('Operating Model'!H8*G$15-'Debt Schedule'!H37)/(Assumptions!C18-Assumptions!C22*$B16),0) -> 1.2362829 | H16: =IFERROR(('Operating Model'!H8*H$15-'Debt Schedule'!H37)/(Assumptions!C18-Assumptions!C22*$B16),0) -> 1.3654392 | I16: =IFERROR(('Operating Model'!H8*I$15-'Debt Schedule'!H37)/(Assumptions!C18-Assumptions!C22*$B16),0) -> 1.4945956
B17: 4.5 | C17: =IFERROR(('Operating Model'!H8*C$15-'Debt Schedule'!H37)/(Assumptions!C18-Assumptions!C22*$B17),0) -> 0.7968171 | D17: =IFERROR(('Operating Model'!H8*D$15-'Debt Schedule'!H37)/(Assumptions!C18-Assumptions!C22*$B17),0) -> 0.93982123 | E17: =IFERROR(('Operating Model'!H8*E$15-'Debt Schedule'!H37)/(Assumptions!C18-Assumptions!C22*$B17),0) -> 1.0828254 | F17: =IFERROR(('Operating Model'!H8*F$15-'Debt Schedule'!H37)/(Assumptions!C18-Assumptions!C22*$B17),0) -> 1.2258295 | G17: =IFERROR(('Operating Model'!H8*G$15-'Debt Schedule'!H37)/(Assumptions!C18-Assumptions!C22*$B17),0) -> 1.3688336 | H17: =IFERROR(('Operating Model'!H8*H$15-'Debt Schedule'!H37)/(Assumptions!C18-Assumptions!C22*$B17),0) -> 1.5118377 | I17: =IFERROR(('Operating Model'!H8*I$15-'Debt Schedule'!H37)/(Assumptions!C18-Assumptions!C22*$B17),0) -> 1.6548419
B18: 5 | C18: =IFERROR(('Operating Model'!H8*C$15-'Debt Schedule'!H37)/(Assumptions!C18-Assumptions!C22*$B18),0) -> 0.89250944 | D18: =IFERROR(('Operating Model'!H8*D$15-'Debt Schedule'!H37)/(Assumptions!C18-Assumptions!C22*$B18),0) -> 1.0526874 | E18: =IFERROR(('Operating Model'!H8*E$15-'Debt Schedule'!H37)/(Assumptions!C18-Assumptions!C22*$B18),0) -> 1.2128653 | F18: =IFERROR(('Operating Model'!H8*F$15-'Debt Schedule'!H37)/(Assumptions!C18-Assumptions!C22*$B18),0) -> 1.3730433 | G18: =IFERROR(('Operating Model'!H8*G$15-'Debt Schedule'!H37)/(Assumptions!C18-Assumptions!C22*$B18),0) -> 1.5332213 | H18: =IFERROR(('Operating Model'!H8*H$15-'Debt Schedule'!H37)/(Assumptions!C18-Assumptions!C22*$B18),0) -> 1.6933992 | I18: =IFERROR(('Operating Model'!H8*I$15-'Debt Schedule'!H37)/(Assumptions!C18-Assumptions!C22*$B18),0) -> 1.8535772
B19: 5.5 | C19: =IFERROR(('Operating Model'!H8*C$15-'Debt Schedule'!H37)/(Assumptions!C18-Assumptions!C22*$B19),0) -> 1.0143227 | D19: =IFERROR(('Operating Model'!H8*D$15-'Debt Schedule'!H37)/(Assumptions!C18-Assumptions!C22*$B19),0) -> 1.1963624 | E19: =IFERROR(('Operating Model'!H8*E$15-'Debt Schedule'!H37)/(Assumptions!C18-Assumptions!C22*$B19),0) -> 1.3784021 | F19: =IFERROR(('Operating Model'!H8*F$15-'Debt Schedule'!H37)/(Assumptions!C18-Assumptions!C22*$B19),0) -> 1.5604418 | G19: =IFERROR(('Operating Model'!H8*G$15-'Debt Schedule'!H37)/(Assumptions!C18-Assumptions!C22*$B19),0) -> 1.7424815 | H19: =IFERROR(('Operating Model'!H8*H$15-'Debt Schedule'!H37)/(Assumptions!C18-Assumptions!C22*$B19),0) -> 1.9245212 | I19: =IFERROR(('Operating Model'!H8*I$15-'Debt Schedule'!H37)/(Assumptions!C18-Assumptions!C22*$B19),0) -> 2.1065608
B20: 6 | C20: =IFERROR(('Operating Model'!H8*C$15-'Debt Schedule'!H37)/(Assumptions!C18-Assumptions!C22*$B20),0) -> 1.1746427 | D20: =IFERROR(('Operating Model'!H8*D$15-'Debt Schedule'!H37)/(Assumptions!C18-Assumptions!C22*$B20),0) -> 1.3854549 | E20: =IFERROR(('Operating Model'!H8*E$15-'Debt Schedule'!H37)/(Assumptions!C18-Assumptions!C22*$B20),0) -> 1.5962671 | F20: =IFERROR(('Operating Model'!H8*F$15-'Debt Schedule'!H37)/(Assumptions!C18-Assumptions!C22*$B20),0) -> 1.8070792 | G20: =IFERROR(('Operating Model'!H8*G$15-'Debt Schedule'!H37)/(Assumptions!C18-Assumptions!C22*$B20),0) -> 2.0178914 | H20: =IFERROR(('Operating Model'!H8*H$15-'Debt Schedule'!H37)/(Assumptions!C18-Assumptions!C22*$B20),0) -> 2.2287036 | I20: =IFERROR(('Operating Model'!H8*I$15-'Debt Schedule'!H37)/(Assumptions!C18-Assumptions!C22*$B20),0) -> 2.4395158
B21: 6.5 | C21: =IFERROR(('Operating Model'!H8*C$15-'Debt Schedule'!H37)/(Assumptions!C18-Assumptions!C22*$B21),0) -> 1.3951557 | D21: =IFERROR(('Operating Model'!H8*D$15-'Debt Schedule'!H37)/(Assumptions!C18-Assumptions!C22*$B21),0) -> 1.6455431 | E21: =IFERROR(('Operating Model'!H8*E$15-'Debt Schedule'!H37)/(Assumptions!C18-Assumptions!C22*$B21),0) -> 1.8959306 | F21: =IFERROR(('Operating Model'!H8*F$15-'Debt Schedule'!H37)/(Assumptions!C18-Assumptions!C22*$B21),0) -> 2.1463181 | G21: =IFERROR(('Operating Model'!H8*G$15-'Debt Schedule'!H37)/(Assumptions!C18-Assumptions!C22*$B21),0) -> 2.3967055 | H21: =IFERROR(('Operating Model'!H8*H$15-'Debt Schedule'!H37)/(Assumptions!C18-Assumptions!C22*$B21),0) -> 2.647093 | I21: =IFERROR(('Operating Model'!H8*I$15-'Debt Schedule'!H37)/(Assumptions!C18-Assumptions!C22*$B21),0) -> 2.8974805
B22: 7 | C22: =IFERROR(('Operating Model'!H8*C$15-'Debt Schedule'!H37)/(Assumptions!C18-Assumptions!C22*$B22),0) -> 1.717596 | D22: =IFERROR(('Operating Model'!H8*D$15-'Debt Schedule'!H37)/(Assumptions!C18-Assumptions!C22*$B22),0) -> 2.0258516 | E22: =IFERROR(('Operating Model'!H8*E$15-'Debt Schedule'!H37)/(Assumptions!C18-Assumptions!C22*$B22),0) -> 2.3341071 | F22: =IFERROR(('Operating Model'!H8*F$15-'Debt Schedule'!H37)/(Assumptions!C18-Assumptions!C22*$B22),0) -> 2.6423627 | G22: =IFERROR(('Operating Model'!H8*G$15-'Debt Schedule'!H37)/(Assumptions!C18-Assumptions!C22*$B22),0) -> 2.9506183 | H22: =IFERROR(('Operating Model'!H8*H$15-'Debt Schedule'!H37)/(Assumptions!C18-Assumptions!C22*$B22),0) -> 3.2588739 | I22: =IFERROR(('Operating Model'!H8*I$15-'Debt Schedule'!H37)/(Assumptions!C18-Assumptions!C22*$B22),0) -> 3.5671294

Sheet Summary
B1: Model Summary & Key Outputs
B3: KEY METRICS OVER HOLD PERIOD
C4: Entry | D4: Year 1 | E4: Year 2 | F4: Year 3 | G4: Year 4 | H4: Year 5
B5: Revenue | C5: ='Operating Model'!C5 -> 17565 | D5: ='Operating Model'!D5 -> 18004.125 | E5: ='Operating Model'!E5 -> 18544.249 | F5: ='Operating Model'!F5 -> 19100.576 | G5: ='Operating Model'!G5 -> 19578.091 | H5: ='Operating Model'!H5 -> 19969.652
B6: EBITDA | C6: ='Operating Model'!C8 -> 1078 | D6: ='Operating Model'!D8 -> 1116.2558 | E6: ='Operating Model'!E8 -> 1205.3762 | F6: ='Operating Model'!F8 -> 1298.8392 | G6: ='Operating Model'!G8 -> 1370.4663 | H6: ='Operating Model'!H8 -> 1437.815
B7: EBITDA Margin | C7: ='Operating Model'!C8/'Operating Model'!C5 -> 0.061372047 | D7: ='Operating Model'!D8/'Operating Model'!D5 -> 0.062 | E7: ='Operating Model'!E8/'Operating Model'!E5 -> 0.065 | F7: ='Operating Model'!F8/'Operating Model'!F5 -> 0.068 | G7: ='Operating Model'!G8/'Operating Model'!G5 -> 0.07 | H7: ='Operating Model'!H8/'Operating Model'!H5 -> 0.072
B8: Total Debt | C8: ='Debt Schedule'!C37 -> 6300 | D8: ='Debt Schedule'!D37 -> 6282.9554 | E8: ='Debt Schedule'!E37 -> 6248.7941 | F8: ='Debt Schedule'!F37 -> 6196.0069 | G8: ='Debt Schedule'!G37 -> 6132.0776 | H8: ='Debt Schedule'!H37 -> 6058.9618
B9: Total Debt / EBITDA | C9: ='Debt Schedule'!C37/'Operating Model'!C8 -> 5.8441558 | D9: =IFERROR('Debt Schedule'!D37/'Operating Model'!D8,0) -> 5.6285985 | E9: =IFERROR('Debt Schedule'!E37/'Operating Model'!E8,0) -> 5.1841029 | F9: =IFERROR('Debt Schedule'!F37/'Operating Model'!F8,0) -> 4.7704188 | G9: =IFERROR('Debt Schedule'!G37/'Operating Model'!G8,0) -> 4.474446 | H9: =IFERROR('Debt Schedule'!H37/'Operating Model'!H8,0) -> 4.2140066
B10: Unlevered FCF | C10: ='Operating Model'!C20 -> 0 | D10: ='Operating Model'!D20 -> 605.08919 | E10: ='Operating Model'!E20 -> 658.70556 | F10: ='Operating Model'!F20 -> 716.58521 | G10: ='Operating Model'!G20 -> 760.8754 | H10: ='Operating Model'!H20 -> 803.19118
B11: Total Cash Interest | C11: ='Debt Schedule'!C38 -> 0 | D11: ='Debt Schedule'!D38 -> 331 | E11: ='Debt Schedule'!E38 -> 322.91255 | F11: ='Debt Schedule'!F38 -> 313.16868 | G11: ='Debt Schedule'!G38 -> 301.61388 | H11: ='Debt Schedule'!H38 -> 288.58112
B13: RETURNS SUMMARY (BASE CASE)
B14: Entry Equity | C14: =Returns!D13 -> 4028.18
B15: Exit Equity (Base) | C15: =Returns!D9 -> 6162.4655
B16: MoM | C16: =Returns!D15 -> 1.5298387
B17: IRR | C17: =Returns!D16 -> 0.088752401
B19: CREDIT METRICS
B20: Interest Coverage Ratio | D20: ='Debt Schedule'!D48 -> 3.3723739 | E20: ='Debt Schedule'!E48 -> 3.7328254 | F20: ='Debt Schedule'!F48 -> 4.1474109 | G20: ='Debt Schedule'!G48 -> 4.5437775 | H20: ='Debt Schedule'!H48 -> 4.9823599
