Workbook

Sheet Cover
B1: DIAGEO PLC — EQUITY RESEARCH MODEL
B4: Integrated 3-Statement Model | DCF & Trading Comps | FY2020A-FY2029E
B6: Company | D6: Diageo PLC
B7: Ticker | D7: DGE LN / LON:DGE
B8: Sector | D8: Beverages — Spirits & Beer
B9: Analyst | D9: Zak Whatmough
B10: Date | D10: April 2025
B11: Share Price | D11: 2,500p (ref price)
B12: Currency | D12: GBP (£m unless stated)
B13: FY end | D13: 30 June
B15: COLOUR LEGEND
B16: ■ | C16: Blue = Input
B17: ■ | C17: Black = Formula
B18: ■ | C18: Green = Cross-sheet link
B19: ■ | C19: Grey = Source note
B21: SHEET INDEX
B22: Assumptions | D22: Key drivers
B23: Income Statement | D23: Revenue to PAT
B24: WC Schedule | D24: DIO/DSO/DPO
B25: Capex & DA | D25: PPE/ROU rollforward
B26: Debt & Interest | D26: Bond + IFRS 16
B27: Div & Buyback | D27: Share count + DPS
B28: Balance Sheet | D28: Integrated, audit check
B29: Cash Flow | D29: CFO/CFI/CFF + UFCF
B30: DCF Valuation | D30: Mid-year, Gordon Growth
B31: Trading Comps | D31: EV/EBITDA + P/E
B32: Charts | D32: Revenue, FCF, leverage, football field

Sheet Assumptions
B1: DIAGEO PLC — KEY ASSUMPTIONS (£m; blue=input, black=formula)
D2: FY2020A | E2: FY2021A | F2: FY2022A | G2: FY2023A | H2: FY2024A | I2: FY2025E | J2: FY2026E | K2: FY2027E | L2: FY2028E | M2: FY2029E
B4: Revenue Assumptions
B5: North America Revenue (£m) | C5: Diageo AR FY24 p.42 | D5: 4500 | E5: 5246 | F5: 6644 | G5: 7190 | H5: 6480 | I5: =H5*(1+I6) | J5: =I5*(1+J6) | K5: =J5*(1+K6) | L5: =K5*(1+L6) | M5: =L5*(1+M6)
B6: NA YoY Growth % | C6: Calc / FactSet consensus | D6: 0 | E6: =(E5-D5)/D5 | F6: =(F5-E5)/E5 | G6: =(G5-F5)/F5 | H6: =(H5-G5)/G5 | I6: =CHOOSE(I43,I45,I46,I47) | J6: =CHOOSE(I43,J45,J46,J47) | K6: =CHOOSE(I43,K45,K46,K47) | L6: =CHOOSE(I43,L45,L46,L47) | M6: =CHOOSE(I43,M45,M46,M47)
B7: International Revenue (£m) | C7: Diageo AR FY24 p.44 | D7: 7252 | E7: 7487 | F7: 8808 | G7: 9923 | H7: 9326 | I7: =H7*(1+I8) | J7: =I7*(1+J8) | K7: =J7*(1+K8) | L7: =K7*(1+L8) | M7: =L7*(1+M8)
B8: Intl YoY Growth % | C8: Calc; Eur+Afr+LatAm+APAC | D8: 0 | E8: =(E7-D7)/D7 | F8: =(F7-E7)/E7 | G8: =(G7-F7)/F7 | H8: =(H7-G7)/G7 | I8: =CHOOSE(I43,I48,I49,I50) | J8: =CHOOSE(I43,J48,J49,J50) | K8: =CHOOSE(I43,K48,K49,K50) | L8: =CHOOSE(I43,L48,L49,L50) | M8: =CHOOSE(I43,M48,M49,M50)
B9: Total Revenue (£m) | D9: =D5+D7 | E9: =E5+E7 | F9: =F5+F7 | G9: =G5+G7 | H9: =H5+H7 | I9: =I5+I7 | J9: =J5+J7 | K9: =K5+K7 | ... M9: =M5+M7
B11: Profitability
B12: Adjusted EBITDA (£m) | C12: Diageo AR FY24 p.30 | D12: 4050 | E12: 4410 | F12: 5320 | G12: 5900 | H12: 5380 | I12: =I13*I9 | J12: =J13*J9 | K12: =K13*K9 | L12: =L13*L9 | M12: =M13*M9
B13: EBITDA Margin % | C13: Calc; premium mix drives margin | D13: =D12/D9 | E13: =E12/E9 | F13: =F12/F9 | G13: =G12/G9 | H13: =H12/H9 | I13: =CHOOSE(I43,I52,I53,I54) | J13: =CHOOSE(I43,J52,J53,J54) | K13: =CHOOSE(I43,K52,K53,K54) | L13: =CHOOSE(I43,L52,L53,L54) | M13: =CHOOSE(I43,M52,M53,M54)
B15: Capex & D&A (detail on Capex & DA tab)
B16: Total Capex (£m) | C16: Distillery expansion programme | D16: 550 | E16: 480 | F16: 620 | G16: 760 | H16: 810 | I16: 850 | J16: 880 | K16: 900 | L16: 920 | M16: 940
B17: Total D&A (£m) | C17: Diageo AR Note 5 p.118 | D17: 680 | E17: 700 | F17: 750 | G17: 810 | H17: 830 | I17: 860 | J17: 880 | K17: 900 | L17: 910 | M17: 920
B19: Finance Costs & Tax
B20: Net Finance Costs (£m) | C20: Declines as bonds mature | D20: 530 | E20: 470 | F20: 500 | G20: 680 | H20: 750 | I20: 720 | J20: 700 | K20: 680 | L20: 660 | M20: 640
B21: Effective Tax Rate | C21: Blended global rate ~22% | D21: 0.208 | E21: 0.195 | F21: 0.202 | G21: 0.21 | H21: 0.225 | I21: 0.22 | J21: 0.22 | K21: 0.22 | L21: 0.22 | M21: 0.22
B23: WACC Build (single column — DCF discount rate)
B24: Risk-Free Rate (10yr Gilt) | C24: Bloomberg Apr-25 UK10Y 4.20% | I24: 0.042
B25: Equity Risk Premium | C25: Damodaran Jan-25 UK ERP 5.5% | I25: 0.055
B26: Levered Beta (2yr weekly) | C26: Bloomberg DGE LN beta=0.75 | I26: 0.75
B27: Cost of Equity (CAPM) | I27: =I24+I26*I25
B28: Pre-tax Cost of Debt | C28: DGE 2032 bond YTM ~4.0% | I28: 0.04
B29: Corp Tax (WACC shield) | I29: =I21
B30: Post-tax Cost of Debt | I30: =I28*(1-I29)
B31: Debt Weight D/(D+E) | C31: FTSE spirits peer median | I31: 0.4
B32: Equity Weight | I32: =1-I31
B33: WACC | I33: =I27*I32+I30*I31
B35: Terminal Value
B36: Terminal Growth Rate (g) | C36: Premium brands; above-inflation pricing | I36: =CHOOSE(I43,I56,I57,I58)
B38: Dividend & Buyback Assumptions
B39: DPS Growth % | C39: Progressive policy; FactSet consensus | D39: 0 | E39: 0.0382 | F39: 0.05 | G39: 0.0501 | H39: 0.0405 | I39: 0.05 | J39: 0.05 | K39: 0.045 | L39: 0.045 | M39: 0.04
B40: Share Buyback (£m) | C40: FY25 guidance ~£1.2bn | D40: 500 | E40: 600 | F40: 1000 | G40: 1250 | H40: 1000 | I40: 1200 | J40: 1200 | K40: 1000 | L40: 1000 | M40: 1000
B42: Scenario Analysis (1=Base, 2=Bull, 3=Bear)
B43: Active Scenario | C43: Change to 1, 2, or 3 | I43: 1
B45: NA Growth — Base | C45: Recovery post-destocking | I45: 0.03 | J45: 0.035 | K45: 0.035 | L45: 0.03 | M45: 0.03
B46: NA Growth — Bull | C46: Strong premiumisation + share gains | I46: 0.05 | J46: 0.055 | K46: 0.05 | L46: 0.045 | M46: 0.04
B47: NA Growth — Bear | C47: Continued destocking + recession | I47: 0.005 | J47: 0.01 | K47: 0.015 | L47: 0.015 | M47: 0.01
B48: Intl Growth — Base | C48: Eur+Afr+LatAm+APAC | I48: 0.04 | J48: 0.045 | K48: 0.04 | L48: 0.035 | M48: 0.035
B49: Intl Growth — Bull | C49: EM volume acceleration | I49: 0.06 | J49: 0.065 | K49: 0.06 | L49: 0.055 | M49: 0.05
...

Sheet Income Statement
B1: DIAGEO PLC — INCOME STATEMENT (£m unless stated)
D2: FY2020A | E2: FY2021A | F2: FY2022A | G2: FY2023A | H2: FY2024A | I2: FY2025E | J2: FY2026E | K2: FY2027E | L2: FY2028E | M2: FY2029E
B4: Revenue
B5: North America | C5: Diageo AR FY24 p.42 | D5: 4500 | E5: 5246 | F5: 6644 | G5: 7190 | H5: 6480 | I5: ='Assumptions'!I5 | J5: ='Assumptions'!J5 | K5: ='Assumptions'!K5 | L5: ='Assumptions'!L5 | M5: ='Assumptions'!M5
B6: International | C6: Diageo AR FY24 p.44 | D6: 7252 | E6: 7487 | F6: 8808 | G6: 9923 | H6: 9326 | I6: ='Assumptions'!I7 | J6: ='Assumptions'!J7 | K6: ='Assumptions'!K7 | L6: ='Assumptions'!L7 | M6: ='Assumptions'!M7
B7: Total Revenue | D7: =D5+D6 | E7: =E5+E6 | F7: =F5+F6 | G7: =G5+G6 | H7: =H5+H6 | I7: =I5+I6 | J7: =J5+J6 | K7: =K5+K6 | ... M7: =M5+M6
B9: Operating Performance
B10: Adjusted EBITDA | C10: Diageo AR FY24 p.30 | D10: 4050 | E10: 4410 | F10: 5320 | G10: 5900 | H10: 5380 | I10: ='Assumptions'!I12 | J10: ='Assumptions'!J12 | K10: ='Assumptions'!K12 | L10: ='Assumptions'!L12 | M10: ='Assumptions'!M12
B11: EBITDA Margin % | D11: =D10/D7 | E11: =E10/E7 | F11: =F10/F7 | G11: =G10/G7 | H11: =H10/H7 | I11: =I10/I7 | J11: =J10/J7 | K11: =K10/K7 | ... M11: =M10/M7
B13: D&A and EBIT
B14: Total D&A | C14: Diageo AR Note 5 p.118 | D14: 680 | E14: 700 | F14: 750 | G14: 810 | H14: 830 | I14: ='Capex & DA'!I21 | J14: ='Capex & DA'!J21 | K14: ='Capex & DA'!K21 | L14: ='Capex & DA'!L21 | M14: ='Capex & DA'!M21
B15: EBIT (Operating Profit) | D15: =D10-D14 | E15: =E10-E14 | F15: =F10-F14 | G15: =G10-G14 | H15: =H10-H14 | I15: =I10-I14 | J15: =J10-J14 | K15: =K10-K14 | ... M15: =M10-M14
B16: EBIT Margin % | D16: =D15/D7 | E16: =E15/E7 | F16: =F15/F7 | G16: =G15/G7 | H16: =H15/H7 | I16: =I15/I7 | J16: =J15/J7 | K16: =K15/K7 | ... M16: =M15/M7
B18: Finance Costs, Tax, PAT
B19: Net Finance Costs | C19: Diageo AR FY24 p.122 | D19: 530 | E19: 470 | F19: 500 | G19: 680 | H19: 750 | I19: ='Debt & Interest'!I20 | J19: ='Debt & Interest'!J20 | K19: ='Debt & Interest'!K20 | L19: ='Debt & Interest'!L20 | M19: ='Debt & Interest'!M20
B20: Profit Before Tax | D20: =D15-D19 | E20: =E15-E19 | F20: =F15-F19 | G20: =G15-G19 | H20: =H15-H19 | I20: =I15-I19 | J20: =J15-J19 | K20: =K15-K19 | ... M20: =M15-M19
B21: Tax Charge | C21: Note 8 p.126 | D21: =D20*'Assumptions'!D21 | E21: =E20*'Assumptions'!E21 | F21: =F20*'Assumptions'!F21 | G21: =G20*'Assumptions'!G21 | H21: =H20*'Assumptions'!H21 | I21: =I20*'Assumptions'!I21 | J21: =J20*'Assumptions'!J21 | K21: =K20*'Assumptions'!K21 | ... M21: =M20*'Assumptions'!M21
B22: Net Income (PAT) | D22: =D20-D21 | E22: =E20-E21 | F22: =F20-F21 | G22: =G20-G21 | H22: =H20-H21 | I22: =I20-I21 | J22: =J20-J21 | K22: =K20-K21 | ... M22: =M20-M21
B23: Net Margin % | D23: =D22/D7 | E23: =E22/E7 | F23: =F22/F7 | G23: =G22/G7 | H23: =H22/H7 | I23: =I22/I7 | J23: =J22/J7 | K23: =K22/K7 | ... M23: =M22/M7
B25: Per Share Metrics
B26: Diluted Shares (m) | C26: Diageo AR FY24 p.134 | D26: 2358 | E26: 2340 | F26: 2305 | G26: 2270 | H26: 2235 | I26: ='Div & Buyback'!I8 | J26: ='Div & Buyback'!J8 | K26: ='Div & Buyback'!K8 | L26: ='Div & Buyback'!L8 | M26: ='Div & Buyback'!M8
B27: EPS (pence) | D27: =D22/D26*100 | E27: =E22/E26*100 | F27: =F22/F26*100 | G27: =G22/G26*100 | H27: =H22/H26*100 | I27: =I22/I26*100 | J27: =J22/J26*100 | K27: =K22/K26*100 | ... M27: =M22/M26*100
B28: DPS (pence) | C28: Diageo AR FY24 p.140 | D28: 69.88 | E28: 72.55 | F28: 76.18 | G28: 80 | H28: 83.24 | I28: ='Div & Buyback'!I11 | J28: ='Div & Buyback'!J11 | K28: ='Div & Buyback'!K11 | L28: ='Div & Buyback'!L11 | M28: ='Div & Buyback'!M11

Sheet WC Schedule
B1: WORKING CAPITAL SCHEDULE (£m; days on total revenue)
D2: FY2020A | E2: FY2021A | F2: FY2022A | G2: FY2023A | H2: FY2024A | I2: FY2025E | J2: FY2026E | K2: FY2027E | L2: FY2028E | M2: FY2029E
B4: Current Assets
B5: Inventories (£m) | C5: Diageo AR Note 15 p.132 | D5: 5800 | E5: 6100 | F5: 6500 | G5: 7200 | H5: 7400 | I5: =ROUND(I6/365*'Income Statement'!I7,0) | J5: =ROUND(J6/365*'Income Statement'!J7,0) | K5: =ROUND(K6/365*'Income Statement'!K7,0) | L5: =ROUND(L6/365*'Income Statement'!L7,0) | M5: =ROUND(M6/365*'Income Statement'!M7,0)
B6: DIO (days) | C6: High DIO reflects maturing stock | D6: =ROUND(D5/'Income Statement'!D7*365,1) | E6: =ROUND(E5/'Income Statement'!E7*365,1) | F6: =ROUND(F5/'Income Statement'!F7*365,1) | G6: =ROUND(G5/'Income Statement'!G7*365,1) | H6: =ROUND(H5/'Income Statement'!H7*365,1) | I6: 168 | J6: 166 | K6: 164 | L6: 162 | M6: 160
B7: Trade Receivables (£m) | C7: Diageo AR Note 16 p.133 | D7: 2100 | E7: 2300 | F7: 2700 | G7: 2900 | H7: 2750 | I7: =ROUND(I8/365*'Income Statement'!I7,0) | J7: =ROUND(J8/365*'Income Statement'!J7,0) | K7: =ROUND(K8/365*'Income Statement'!K7,0) | L7: =ROUND(L8/365*'Income Statement'!L7,0) | M7: =ROUND(M8/365*'Income Statement'!M7,0)
B8: DSO (days) | C8: Wholesale/distributor terms | D8: =ROUND(D7/'Income Statement'!D7*365,1) | E8: =ROUND(E7/'Income Statement'!E7*365,1) | F8: =ROUND(F7/'Income Statement'!F7*365,1) | G8: =ROUND(G7/'Income Statement'!G7*365,1) | H8: =ROUND(H7/'Income Statement'!H7*365,1) | I8: 63 | J8: 62.5 | K8: 62 | L8: 61.5 | M8: 61
B9: Other Current Assets (£m) | C9: Note 14 p.131 | D9: 500 | E9: 520 | F9: 560 | G9: 580 | H9: 600 | I9: =ROUND('Income Statement'!I7*0.036,0) | J9: =ROUND('Income Statement'!J7*0.036,0) | K9: =ROUND('Income Statement'!K7*0.036,0) | L9: =ROUND('Income Statement'!L7*0.036,0) | M9: =ROUND('Income Statement'!M7*0.036,0)
B11: Current Liabilities
B12: Trade Payables (£m) | C12: Diageo AR Note 19 p.136 | D12: 3200 | E12: 3400 | F12: 3800 | G12: 4100 | H12: 3900 | I12: =ROUND(I13/365*'Income Statement'!I7,0) | J12: =ROUND(J13/365*'Income Statement'!J7,0) | K12: =ROUND(K13/365*'Income Statement'!K7,0) | L12: =ROUND(L13/365*'Income Statement'!L7,0) | M12: =ROUND(M13/365*'Income Statement'!M7,0)
B13: DPO (days) | C13: Stable supplier payment terms | D13: =ROUND(D12/'Income Statement'!D7*365,1) | E13: =ROUND(E12/'Income Statement'!E7*365,1) | F13: =ROUND(F12/'Income Statement'!F7*365,1) | G13: =ROUND(G12/'Income Statement'!G7*365,1) | H13: =ROUND(H12/'Income Statement'!H7*365,1) | I13: 90 | J13: 90 | K13: 91 | L13: 91 | M13: 92
B14: Current Lease Liabilities (£m) | C14: Note 22 p.139 | D14: 120 | E14: 125 | F14: 130 | G14: 135 | H14: 140 | I14: =ROUND('Income Statement'!I7*0.008,0) | J14: =ROUND('Income Statement'!J7*0.008,0) | K14: =ROUND('Income Statement'!K7*0.008,0) | L14: =ROUND('Income Statement'!L7*0.008,0) | M14: =ROUND('Income Statement'!M7*0.008,0)
B15: Other Current Liabilities (£m) | C15: Note 19 p.136 | D15: 2400 | E15: 2500 | F15: 2700 | G15: 2900 | H15: 2800 | I15: =ROUND('Income Statement'!I7*0.168,0) | J15: =ROUND('Income Statement'!J7*0.168,0) | K15: =ROUND('Income Statement'!K7*0.168,0) | L15: =ROUND('Income Statement'!L7*0.168,0) | M15: =ROUND('Income Statement'!M7*0.168,0)
B17: Net Working Capital
B18: Net Working Capital (£m) | C18: Inv+Recv+OthCA-Pay-CurrLease-OthCL | D18: =D5+D7+D9-D12-D14-D15 | E18: =E5+E7+E9-E12-E14-E15 | F18: =F5+F7+F9-F12-F14-F15 | G18: =G5+G7+G9-G12-G14-G15 | H18: =H5+H7+H9-H12-H14-H15 | I18: =I5+I7+I9-I12-I14-I15 | J18: =J5+J7+J9-J12-J14-J15 | K18: =K5+K7+K9-K12-K14-K15 | ... M18: =M5+M7+M9-M12-M14-M15
B19: Change in NWC [+=cash out] | C19: delta NWC = NWC(t) - NWC(t-1) | D19: =0 | E19: =E18-D18 | F19: =F18-E18 | G19: =G18-F18 | H19: =H18-G18 | I19: =I18-H18 | J19: =J18-I18 | K19: =K18-J18 | L19: =L18-K18 | M19: =M18-L18

Sheet Capex & DA
B1: CAPEX & D&A SCHEDULE (£m)
D2: FY2020A | E2: FY2021A | F2: FY2022A | G2: FY2023A | H2: FY2024A | I2: FY2025E | J2: FY2026E | K2: FY2027E | L2: FY2028E | M2: FY2029E
B4: PP&E Rollforward (net book value)
B5: Opening PP&E (net) | C5: Diageo AR FY20 BS | D5: 4800 | E5: =D8 | F5: =E8 | G5: =F8 | H5: =G8 | I5: =H8 | J5: =I8 | K5: =J8 | L5: =K8 | M5: =L8
B6: Capex Additions | C6: Diageo AR p.140 | D6: 550 | E6: 480 | F6: 620 | G6: 760 | H6: 810 | I6: ='Assumptions'!I16 | J6: ='Assumptions'!J16 | K6: ='Assumptions'!K16 | L6: ='Assumptions'!L16 | M6: ='Assumptions'!M16
B7: Less: PP&E Depreciation | C7: Diageo AR Note 10 p.128 | D7: 420 | E7: 430 | F7: 450 | G7: 480 | H7: 500 | I7: 520 | J7: 530 | K7: 540 | L7: 550 | M7: 560
B8: Closing PP&E (net) | D8: =D5+D6-D7 | E8: =E5+E6-E7 | F8: =F5+F6-F7 | G8: =G5+G6-G7 | H8: =H5+H6-H7 | I8: =I5+I6-I7 | J8: =J5+J6-J7 | K8: =K5+K6-K7 | ... M8: =M5+M6-M7
B10: Right-of-Use Asset Rollforward (IFRS 16)
B11: Opening ROU Asset | C11: Diageo AR FY20 | D11: 780 | E11: =D14 | F11: =E14 | G11: =F14 | H11: =G14 | I11: =H14 | J11: =I14 | K11: =J14 | L11: =K14 | M11: =L14
B12: New Leases / Remeasurements | C12: Diageo AR Note 11 p.129 | D12: 100 | E12: 105 | F12: 120 | G12: 135 | H12: 140 | I12: 140 | J12: 140 | K12: 145 | L12: 145 | M12: 150
B13: Less: ROU Depreciation | C13: Diageo AR Note 11 p.129 | D13: 130 | E13: 135 | F13: 140 | G13: 145 | H13: 150 | I13: 155 | J13: 160 | K13: 165 | L13: 170 | M13: 175
B14: Closing ROU Asset | D14: =D11+D12-D13 | E14: =E11+E12-E13 | F14: =F11+F12-F13 | G14: =G11+G12-G13 | H14: =H11+H12-H13 | I14: =I11+I12-I13 | J14: =J11+J12-J13 | K14: =K11+K12-K13 | ... M14: =M11+M12-M13
B16: Goodwill, Brands & Intangibles
B17: Goodwill & Brands (£m) | C17: Diageo AR Note 9 p.124 (no amort, IFRS) | D17: 16200 | E17: 16550 | F17: 17100 | G17: 17550 | H17: 17800 | I17: 17800 | J17: 17800 | K17: 17800 | L17: 17800 | M17: 17800
B18: Intangible Amortisation (finite life) | C18: Note 9; software + licences | D18: 130 | E18: 135 | F18: 160 | G18: 185 | H18: 180 | I18: 185 | J18: 190 | K18: 195 | L18: 190 | M18: 185
B20: Summary
B21: Total D&A | D21: =D7+D13+D18 | E21: =E7+E13+E18 | F21: =F7+F13+F18 | G21: =G7+G13+G18 | H21: =H7+H13+H18 | I21: =I7+I13+I18 | J21: =J7+J13+J18 | K21: =K7+K13+K18 | ... M21: =M7+M13+M18
B22: Total Capex | C22: Capex additions above | D22: =D6 | E22: =E6 | F22: =F6 | G22: =G6 | H22: =H6 | I22: =I6 | J22: =J6 | K22: =K6 | ... M22: =M6
B23: Capex / Revenue % | D23: =D6/'Income Statement'!D7 | E23: =E6/'Income Statement'!E7 | F23: =F6/'Income Statement'!F7 | G23: =G6/'Income Statement'!G7 | H23: =H6/'Income Statement'!H7 | I23: =I6/'Income Statement'!I7 | J23: =J6/'Income Statement'!J7 | K23: =K6/'Income Statement'!K7 | ... M23: =M6/'Income Statement'!M7

Sheet Debt & Interest
B1: DEBT & INTEREST SCHEDULE (£m)
D2: FY2020A | E2: FY2021A | F2: FY2022A | G2: FY2023A | H2: FY2024A | I2: FY2025E | J2: FY2026E | K2: FY2027E | L2: FY2028E | M2: FY2029E
B4: Bond / Drawn Debt Rollforward
B5: Opening Drawn Debt | C5: Diageo AR FY20 | D5: 13500 | E5: =D7 | F5: =E7 | G5: =F7 | H5: =G7 | I5: =H7 | J5: =I7 | K5: =J7 | L5: =K7 | M5: =L7
B6: Net Repayments / (Issuance) | C6: Deleveraging £400-500m/yr | D6: 0 | E6: -700 | F6: -1800 | G6: -900 | H6: 0 | I6: 400 | J6: 400 | K6: 500 | L6: 500 | M6: 500
B7: Closing Drawn Debt | D7: =D5-D6 | E7: =E5-E6 | F7: =F5-F6 | G7: =G5-G6 | H7: =H5-H6 | I7: =I5-I6 | J7: =J5-J6 | K7: =K5-K6 | ... M7: =M5-M6
B8: Blended Coupon Rate | C8: Bloomberg DGE bond curves; IG credit | D8: 0.03 | E8: 0.03 | F8: 0.03 | G8: 0.03 | H8: 0.03 | I8: 0.03 | J8: 0.03 | K8: 0.03 | L8: 0.03 | M8: 0.03
B9: Cash Interest on Debt | D9: =(D5+D7)/2*D8 | E9: =(E5+E7)/2*E8 | F9: =(F5+F7)/2*F8 | G9: =(G5+G7)/2*G8 | H9: =(H5+H7)/2*H8 | I9: =(I5+I7)/2*I8 | J9: =(J5+J7)/2*J8 | K9: =(K5+K7)/2*K8 | ... M9: =(M5+M7)/2*M8
B11: Lease Liabilities (IFRS 16)
B12: Opening Lease Liabilities | C12: Diageo AR FY20 | D12: 800 | E12: =D15 | F12: =E15 | G12: =F15 | H12: =G15 | I12: =H15 | J12: =I15 | K12: =J15 | L12: =K15 | M12: =L15
B13: New Leases | C13: Note 11 p.129 | D13: 95 | E13: 105 | F13: 120 | G13: 135 | H13: 140 | I13: 140 | J13: 140 | K13: 145 | L13: 145 | M13: 150
B14: Less: Lease Principal Payments | C14: CFS lease repayments | D14: 120 | E14: 130 | F14: 135 | G14: 140 | H14: 145 | I14: 155 | J14: 160 | K14: 165 | L14: 170 | M14: 175
B15: Closing Lease Liabilities | D15: =D12+D13-D14 | E15: =E12+E13-E14 | F15: =F12+F13-F14 | G15: =G12+G13-G14 | H15: =H12+H13-H14 | I15: =I12+I13-I14 | J15: =J12+J13-J14 | K15: =K12+K13-K14 | ... M15: =M12+M13-M14
B16: Implied Lease Rate | C16: Blended incremental borrowing rate | D16: 0.05 | E16: 0.05 | F16: 0.05 | G16: 0.05 | H16: 0.05 | I16: 0.05 | J16: 0.05 | K16: 0.05 | L16: 0.05 | M16: 0.05
B17: Interest on Leases | D17: =(D12+D15)/2*D16 | E17: =(E12+E15)/2*E16 | F17: =(F12+F15)/2*F16 | G17: =(G12+G15)/2*G16 | H17: =(H12+H15)/2*H16 | I17: =(I12+I15)/2*I16 | J17: =(J12+J15)/2*J16 | K17: =(K12+K15)/2*K16 | ... M17: =(M12+M15)/2*M16
B19: Finance Charge Summary
B20: Total Finance Charges | D20: =D9+D17 | E20: =E9+E17 | F20: =F9+F17 | G20: =G9+G17 | H20: =H9+H17 | I20: =I9+I17 | J20: =J9+J17 | K20: =K9+K17 | ... M20: =M9+M17
B22: Net Debt Bridge
B23: Cash & Equivalents | C23: From Balance Sheet | D23: 2900 | E23: 2600 | F23: 2400 | G23: 2300 | H23: 2100 | I23: ='Balance Sheet'!I5 | J23: ='Balance Sheet'!J5 | K23: ='Balance Sheet'!K5 | L23: ='Balance Sheet'!L5 | M23: ='Balance Sheet'!M5
B24: Gross Drawn Debt | D24: =D7 | E24: =E7 | F24: =F7 | G24: =G7 | H24: =H7 | I24: =I7 | J24: =J7 | K24: =K7 | ... M24: =M7
B25: Gross Lease Liabilities | D25: =D15 | E25: =E15 | F25: =F15 | G25: =G15 | H25: =H15 | I25: =I15 | J25: =J15 | K25: =K15 | ... M25: =M15
B26: Net Debt (exc. leases) | D26: =D24-D23 | E26: =E24-E23 | F26: =F24-F23 | G26: =G24-G23 | H26: =H24-H23 | I26: =I24-I23 | J26: =J24-J23 | K26: =K24-K23 | ... M26: =M24-M23
B27: Net Debt (inc. leases) | D27: =D24+D25-D23 | E27: =E24+E25-E23 | F27: =F24+F25-F23 | G27: =G24+G25-G23 | H27: =H24+H25-H23 | I27: =I24+I25-I23 | J27: =J24+J25-J23 | K27: =K24+K25-K23 | ... M27: =M24+M25-M23

Sheet Div & Buyback
B1: DIVIDEND & BUYBACK SCHEDULE (£m unless stated)
D2: FY2020A | E2: FY2021A | F2: FY2022A | G2: FY2023A | H2: FY2024A | I2: FY2025E | J2: FY2026E | K2: FY2027E | L2: FY2028E | M2: FY2029E
B4: Share Count Rollforward
B5: Opening Shares (m) | C5: Diageo AR FY20 | D5: 2358 | E5: =D7 | F5: =E7 | G5: =F7 | H5: =G7 | I5: =H7 | J5: =I7 | K5: =J7 | L5: =K7 | M5: =L7
B6: Buyback (shares retired, m) | C6: BB £m / avg £25/share | D6: 20 | E6: 24 | F6: 40 | G6: 50 | H6: 40 | I6: =ROUND('Assumptions'!I40/25,0) | J6: =ROUND('Assumptions'!J40/25,0) | K6: =ROUND('Assumptions'!K40/25,0) | L6: =ROUND('Assumptions'!L40/25,0) | M6: =ROUND('Assumptions'!M40/25,0)
B7: Closing Shares (m) | D7: =D5-D6 | E7: =E5-E6 | F7: =F5-F6 | G7: =G5-G6 | H7: =H5-H6 | I7: =I5-I6 | J7: =J5-J6 | K7: =K5-K6 | ... M7: =M5-M6
B8: Weighted Avg Diluted (m) | D8: =ROUND((D5+D7)/2,0) | E8: =ROUND((E5+E7)/2,0) | F8: =ROUND((F5+F7)/2,0) | G8: =ROUND((G5+G7)/2,0) | H8: =ROUND((H5+H7)/2,0) | I8: =ROUND((I5+I7)/2,0) | J8: =ROUND((J5+J7)/2,0) | K8: =ROUND((K5+K7)/2,0) | ... M8: =ROUND((M5+M7)/2,0)
B10: Dividend & Buyback
B11: DPS (pence) | C11: Diageo AR FY24 p.140 | D11: 69.88 | E11: 72.55 | F11: 76.18 | G11: 80 | H11: 83.24 | I11: =H11*(1+'Assumptions'!I39) | J11: =I11*(1+'Assumptions'!J39) | K11: =J11*(1+'Assumptions'!K39) | L11: =K11*(1+'Assumptions'!L39) | M11: =L11*(1+'Assumptions'!M39)
B12: Total Dividend (£m) | D12: =ROUND(D11*D8/100,0) | E12: =ROUND(E11*E8/100,0) | F12: =ROUND(F11*F8/100,0) | G12: =ROUND(G11*G8/100,0) | H12: =ROUND(H11*H8/100,0) | I12: =ROUND(I11*I8/100,0) | J12: =ROUND(J11*J8/100,0) | K12: =ROUND(K11*K8/100,0) | ... M12: =ROUND(M11*M8/100,0)
B13: Share Buyback (£m) | C13: From Assumptions | D13: 500 | E13: 600 | F13: 1000 | G13: 1250 | H13: 1000 | I13: ='Assumptions'!I40 | J13: ='Assumptions'!J40 | K13: ='Assumptions'!K40 | L13: ='Assumptions'!L40 | M13: ='Assumptions'!M40
B14: Total Capital Distribution | D14: =D12+D13 | E14: =E12+E13 | F14: =F12+F13 | G14: =G12+G13 | H14: =H12+H13 | I14: =I12+I13 | J14: =J12+J13 | K14: =K12+K13 | ... M14: =M12+M13
B16: Return Metrics
B17: Payout Ratio (Div/PAT) | D17: =D12/'Income Statement'!D22 | E17: =E12/'Income Statement'!E22 | F17: =F12/'Income Statement'!F22 | G17: =G12/'Income Statement'!G22 | H17: =H12/'Income Statement'!H22 | I17: =I12/'Income Statement'!I22 | J17: =J12/'Income Statement'!J22 | K17: =K12/'Income Statement'!K22 | ... M17: =M12/'Income Statement'!M22
B18: Dividend Yield (at 2500p) | D18: =D11/2500 | E18: =E11/2500 | F18: =F11/2500 | G18: =G11/2500 | H18: =H11/2500 | I18: =I11/2500 | J18: =J11/2500 | K18: =K11/2500 | ... M18: =M11/2500

Sheet Balance Sheet
B1: DIAGEO PLC — BALANCE SHEET (£m)
D2: FY2020A | E2: FY2021A | F2: FY2022A | G2: FY2023A | H2: FY2024A | I2: FY2025E | J2: FY2026E | K2: FY2027E | L2: FY2028E | M2: FY2029E
B4: Current Assets
B5: Cash & Equivalents | C5: Diageo AR p.132 / Cash Flow closing | D5: 2900 | E5: 2600 | F5: 2400 | G5: 2300 | H5: 2100 | I5: ='Cash Flow'!I31 | J5: ='Cash Flow'!J31 | K5: ='Cash Flow'!K31 | L5: ='Cash Flow'!L31 | M5: ='Cash Flow'!M31
B6: Inventories | C6: WC Schedule | D6: 5800 | E6: 6100 | F6: 6500 | G6: 7200 | H6: 7400 | I6: ='WC Schedule'!I5 | J6: ='WC Schedule'!J5 | K6: ='WC Schedule'!K5 | L6: ='WC Schedule'!L5 | M6: ='WC Schedule'!M5
B7: Trade & Other Receivables | C7: WC Schedule | D7: 2100 | E7: 2300 | F7: 2700 | G7: 2900 | H7: 2750 | I7: ='WC Schedule'!I7 | J7: ='WC Schedule'!J7 | K7: ='WC Schedule'!K7 | L7: ='WC Schedule'!L7 | M7: ='WC Schedule'!M7
B8: Other Current Assets | C8: WC Schedule | D8: 500 | E8: 520 | F8: 560 | G8: 580 | H8: 600 | I8: ='WC Schedule'!I9 | J8: ='WC Schedule'!J9 | K8: ='WC Schedule'!K9 | L8: ='WC Schedule'!L9 | M8: ='WC Schedule'!M9
B9: Total Current Assets | D9: =D5+D6+D7+D8 | E9: =E5+E6+E7+E8 | F9: =F5+F6+F7+F8 | G9: =G5+G6+G7+G8 | H9: =H5+H6+H7+H8 | I9: =I5+I6+I7+I8 | J9: =J5+J6+J7+J8 | K9: =K5+K6+K7+K8 | ... M9: =M5+M6+M7+M8
B11: Non-Current Assets
B12: PP&E (net) | C12: Capex & DA Schedule | D12: 4800 | E12: 4650 | F12: 4580 | G12: 4700 | H12: 4850 | I12: ='Capex & DA'!I8 | J12: ='Capex & DA'!J8 | K12: ='Capex & DA'!K8 | L12: ='Capex & DA'!L8 | M12: ='Capex & DA'!M8
B13: Right-of-Use Assets | C13: Capex & DA Schedule | D13: 780 | E13: 750 | F13: 730 | G13: 720 | H13: 710 | I13: ='Capex & DA'!I14 | J13: ='Capex & DA'!J14 | K13: ='Capex & DA'!K14 | L13: ='Capex & DA'!L14 | M13: ='Capex & DA'!M14
B14: Goodwill, Brands & Intangibles | C14: Capex & DA Schedule | D14: 16200 | E14: 16550 | F14: 17100 | G14: 17550 | H14: 17800 | I14: ='Capex & DA'!I17 | J14: ='Capex & DA'!J17 | K14: ='Capex & DA'!K17 | L14: ='Capex & DA'!L17 | M14: ='Capex & DA'!M17
B15: Other Non-Current Assets | C15: Associates, pension; grows ~2% p.a. | D15: 4000 | E15: 4050 | F15: 4100 | G15: 4200 | H15: 4200 | I15: =ROUND(H15*1.02,0) | J15: =ROUND(I15*1.02,0) | K15: =ROUND(J15*1.02,0) | L15: =ROUND(K15*1.02,0) | M15: =ROUND(L15*1.02,0)
B16: Total Non-Current Assets | D16: =D12+D13+D14+D15 | E16: =E12+E13+E14+E15 | F16: =F12+F13+F14+F15 | G16: =G12+G13+G14+G15 | H16: =H12+H13+H14+H15 | I16: =I12+I13+I14+I15 | J16: =J12+J13+J14+J15 | K16: =K12+K13+K14+K15 | ... M16: =M12+M13+M14+M15
B18: TOTAL ASSETS | D18: =D9+D16 | E18: =E9+E16 | F18: =F9+F16 | G18: =G9+G16 | H18: =H9+H16 | I18: =I9+I16 | J18: =J9+J16 | K18: =K9+K16 | ... M18: =M9+M16
B20: Current Liabilities
B21: Trade & Other Payables | C21: WC Schedule | D21: 3200 | E21: 3400 | F21: 3800 | G21: 4100 | H21: 3900 | I21: ='WC Schedule'!I12 | J21: ='WC Schedule'!J12 | K21: ='WC Schedule'!K12 | L21: ='WC Schedule'!L12 | M21: ='WC Schedule'!M12
B22: Short-Term Borrowings | C22: ~15% of total bonds | D22: 1500 | E22: 2200 | F22: 2800 | G22: 2100 | H22: 1800 | I22: =ROUND('Debt & Interest'!I7*0.15,0) | J22: =ROUND('Debt & Interest'!J7*0.15,0) | K22: =ROUND('Debt & Interest'!K7*0.15,0) | L22: =ROUND('Debt & Interest'!L7*0.15,0) | M22: =ROUND('Debt & Interest'!M7*0.15,0)
B23: Current Lease Liabilities | C23: WC Schedule | D23: 120 | E23: 125 | F23: 130 | G23: 135 | H23: 140 | I23: ='WC Schedule'!I14 | J23: ='WC Schedule'!J14 | K23: ='WC Schedule'!K14 | L23: ='WC Schedule'!L14 | M23: ='WC Schedule'!M14
B24: Other Current Liabilities | C24: WC Schedule | D24: 2400 | E24: 2500 | F24: 2700 | G24: 2900 | H24: 2800 | I24: ='WC Schedule'!I15 | J24: ='WC Schedule'!J15 | K24: ='WC Schedule'!K15 | L24: ='WC Schedule'!L15 | M24: ='WC Schedule'!M15
B25: Total Current Liabilities | D25: =D21+D22+D23+D24 | E25: =E21+E22+E23+E24 | F25: =F21+F22+F23+F24 | G25: =G21+G22+G23+G24 | H25: =H21+H22+H23+H24 | I25: =I21+I22+I23+I24 | J25: =J21+J22+J23+J24 | K25: =K21+K22+K23+K24 | ... M25: =M21+M22+M23+M24
B27: Non-Current Liabilities
B28: Long-Term Borrowings | C28: 85% of Debt Schedule closing | D28: 12000 | E28: 12000 | F28: 13200 | G28: 14800 | H28: 15100 | I28: =ROUND('Debt & Interest'!I7*0.85,0) | J28: =ROUND('Debt & Interest'!J7*0.85,0) | K28: =ROUND('Debt & Interest'!K7*0.85,0) | L28: =ROUND('Debt & Interest'!L7*0.85,0) | M28: =ROUND('Debt & Interest'!M7*0.85,0)
B29: Long-Term Lease Liabilities | C29: Debt Schedule | D29: 680 | E29: 650 | F29: 630 | G29: 620 | H29: 610 | I29: ='Debt & Interest'!I15-'WC Schedule'!I14 | J29: ='Debt & Interest'!J15-'WC Schedule'!J14 | K29: ='Debt & Interest'!K15-'WC Schedule'!K14 | L29: ='Debt & Interest'!L15-'WC Schedule'!L14 | M29: ='Debt & Interest'!M15-'WC Schedule'!M14
B30: Deferred Tax | C30: Note 8 p.126; grows ~2% p.a. | D30: 2800 | E30: 2900 | F30: 3000 | G30: 3100 | H30: 3200 | I30: =ROUND(H30*1.02,0) | J30: =ROUND(I30*1.02,0) | K30: =ROUND(J30*1.02,0) | L30: =ROUND(K30*1.02,0) | M30: =ROUND(L30*1.02,0)
B31: Total Non-Current Liabilities | D31: =D28+D29+D30 | E31: =E28+E29+E30 | F31: =F28+F29+F30 | G31: =G28+G29+G30 | H31: =H28+H29+H30 | I31: =I28+I29+I30 | J31: =J28+J29+J30 | K31: =K28+K29+K30 | ... M31: =M28+M29+M30
B33: TOTAL LIABILITIES | D33: =D25+D31 | E33: =E25+E31 | F33: =F25+F31 | G33: =G25+G31 | H33: =H25+H31 | I33: =I25+I31 | J33: =J25+J31 | K33: =K25+K31 | ... M33: =M25+M31
B34: NET ASSETS | D34: =D18-D33 | E34: =E18-E33 | F34: =F18-F33 | G34: =G18-G33 | H34: =H18-H33 | I34: =I18-I33 | J34: =J18-J33 | K34: =K18-K33 | ... M34: =M18-M33
B36: Shareholders' Equity
B37: Shareholders' Equity | C37: Prior equity + PAT - Dividends - Buybacks | D37: 14380 | E37: 13745 | F37: 12410 | G37: 12395 | H37: 12860 | I37: =H37+'Income Statement'!I22-'Div & Buyback'!I12-'Div & Buyback'!I13 | J37: =I37+'Income Statement'!J22-'Div & Buyback'!J12-'Div & Buyback'!J13 | K37: =J37+'Income Statement'!K22-'Div & Buyback'!K12-'Div & Buyback'!K13 | L37: =K37+'Income Statement'!L22-'Div & Buyback'!L12-'Div & Buyback'!L13 | M37: =L37+'Income Statement'!M22-'Div & Buyback'!M12-'Div & Buyback'!M13
B38: TOTAL EQUITY | D38: =D37 | E38: =E37 | F38: =F37 | G38: =G37 | H38: =H37 | I38: =I37 | J38: =J37 | K38: =K37 | ... M38: =M37
B40: AUDIT: Assets - Liab - Equity (should be 0) | D40: =D18-D33-D38 | E40: =E18-E33-E38 | F40: =F18-F33-F38 | G40: =G18-G33-G38 | H40: =H18-H33-H38 | I40: =I18-I33-I38 | J40: =J18-J33-J38 | K40: =K18-K33-K38 | ... M40: =M18-M33-M38

Sheet Cash Flow
B1: DIAGEO PLC — CASH FLOW STATEMENT (£m)
D2: FY2020A | E2: FY2021A | F2: FY2022A | G2: FY2023A | H2: FY2024A | I2: FY2025E | J2: FY2026E | K2: FY2027E | L2: FY2028E | M2: FY2029E
B4: Cash Flow from Operations
B5: EBITDA | D5: ='Income Statement'!D10 | E5: ='Income Statement'!E10 | F5: ='Income Statement'!F10 | G5: ='Income Statement'!G10 | H5: ='Income Statement'!H10 | I5: ='Income Statement'!I10 | J5: ='Income Statement'!J10 | K5: ='Income Statement'!K10 | ... M5: ='Income Statement'!M10
B6: Less: Tax Paid | D6: =-'Income Statement'!D21 | E6: =-'Income Statement'!E21 | F6: =-'Income Statement'!F21 | G6: =-'Income Statement'!G21 | H6: =-'Income Statement'!H21 | I6: =-'Income Statement'!I21 | J6: =-'Income Statement'!J21 | K6: =-'Income Statement'!K21 | ... M6: =-'Income Statement'!M21
B7: Less: Change in Working Capital | D7: =-'WC Schedule'!D19 | E7: =-'WC Schedule'!E19 | F7: =-'WC Schedule'!F19 | G7: =-'WC Schedule'!G19 | H7: =-'WC Schedule'!H19 | I7: =-'WC Schedule'!I19 | J7: =-'WC Schedule'!J19 | K7: =-'WC Schedule'!K19 | ... M7: =-'WC Schedule'!M19
B8: Other Operating Items | C8: SBC, pensions, provisions (AR p.142); held flat | D8: 40 | E8: 40 | F8: 40 | G8: 40 | H8: 40 | I8: 40 | J8: 40 | K8: 40 | L8: 40 | M8: 40
B9: Cash Flow from Operations | D9: =D5+D6+D7+D8 | E9: =E5+E6+E7+E8 | F9: =F5+F6+F7+F8 | G9: =G5+G6+G7+G8 | H9: =H5+H6+H7+H8 | I9: =I5+I6+I7+I8 | J9: =J5+J6+J7+J8 | K9: =K5+K6+K7+K8 | ... M9: =M5+M6+M7+M8
B11: Cash Flow from Investing
B12: Capital Expenditure | D12: =-'Capex & DA'!D6 | E12: =-'Capex & DA'!E6 | F12: =-'Capex & DA'!F6 | G12: =-'Capex & DA'!G6 | H12: =-'Capex & DA'!H6 | I12: =-'Capex & DA'!I6 | J12: =-'Capex & DA'!J6 | K12: =-'Capex & DA'!K6 | ... M12: =-'Capex & DA'!M6
B13: Disposal Proceeds | C13: Diageo AR p.142; nominal | D13: 15 | E13: 15 | F13: 15 | G13: 15 | H13: 15 | I13: 15 | J13: 15 | K13: 15 | L13: 15 | M13: 15
B14: Cash Flow from Investing | D14: =D12+D13 | E14: =E12+E13 | F14: =F12+F13 | G14: =G12+G13 | H14: =H12+H13 | I14: =I12+I13 | J14: =J12+J13 | K14: =K12+K13 | ... M14: =M12+M13
B16: Cash Flow from Financing
B17: Debt Repayments / (Issuance) | D17: =-'Debt & Interest'!D6 | E17: =-'Debt & Interest'!E6 | F17: =-'Debt & Interest'!F6 | G17: =-'Debt & Interest'!G6 | H17: =-'Debt & Interest'!H6 | I17: =-'Debt & Interest'!I6 | J17: =-'Debt & Interest'!J6 | K17: =-'Debt & Interest'!K6 | ... M17: =-'Debt & Interest'!M6
B18: Lease Principal Payments | D18: =-'Debt & Interest'!D14 | E18: =-'Debt & Interest'!E14 | F18: =-'Debt & Interest'!F14 | G18: =-'Debt & Interest'!G14 | H18: =-'Debt & Interest'!H14 | I18: =-'Debt & Interest'!I14 | J18: =-'Debt & Interest'!J14 | K18: =-'Debt & Interest'!K14 | ... M18: =-'Debt & Interest'!M14
B19: Interest Paid | D19: =-'Debt & Interest'!D20 | E19: =-'Debt & Interest'!E20 | F19: =-'Debt & Interest'!F20 | G19: =-'Debt & Interest'!G20 | H19: =-'Debt & Interest'!H20 | I19: =-'Debt & Interest'!I20 | J19: =-'Debt & Interest'!J20 | K19: =-'Debt & Interest'!K20 | ... M19: =-'Debt & Interest'!M20
B20: Dividends Paid | D20: =-'Div & Buyback'!D12 | E20: =-'Div & Buyback'!E12 | F20: =-'Div & Buyback'!F12 | G20: =-'Div & Buyback'!G12 | H20: =-'Div & Buyback'!H12 | I20: =-'Div & Buyback'!I12 | J20: =-'Div & Buyback'!J12 | K20: =-'Div & Buyback'!K12 | ... M20: =-'Div & Buyback'!M12
B21: Share Buybacks | D21: =-'Div & Buyback'!D13 | E21: =-'Div & Buyback'!E13 | F21: =-'Div & Buyback'!F13 | G21: =-'Div & Buyback'!G13 | H21: =-'Div & Buyback'!H13 | I21: =-'Div & Buyback'!I13 | J21: =-'Div & Buyback'!J13 | K21: =-'Div & Buyback'!K13 | ... M21: =-'Div & Buyback'!M13
B22: Cash Flow from Financing | D22: =D17+D18+D19+D20+D21 | E22: =E17+E18+E19+E20+E21 | F22: =F17+F18+F19+F20+F21 | G22: =G17+G18+G19+G20+G21 | H22: =H17+H18+H19+H20+H21 | I22: =I17+I18+I19+I20+I21 | J22: =J17+J18+J19+J20+J21 | K22: =K17+K18+K19+K20+K21 | ... M22: =M17+M18+M19+M20+M21
B24: Free Cash Flow
B25: Unlevered FCF (EBITDA-Tax-Capex-delta WC) | D25: =D5+D6+D12+D7 | E25: =E5+E6+E12+E7 | F25: =F5+F6+F12+F7 | G25: =G5+G6+G12+G7 | H25: =H5+H6+H12+H7 | I25: =I5+I6+I12+I7 | J25: =J5+J6+J12+J7 | K25: =K5+K6+K12+K7 | ... M25: =M5+M6+M12+M7
B26: Levered FCF (CFO+CFI) | D26: =D9+D14 | E26: =E9+E14 | F26: =F9+F14 | G26: =G9+G14 | H26: =H9+H14 | I26: =I9+I14 | J26: =J9+J14 | K26: =K9+K14 | ... M26: =M9+M14
B28: Cash Movement
B29: Opening Cash | C29: FY20 opening = FY19 closing | D29: 2900 | E29: =D31 | F29: =E31 | G29: =F31 | H29: =G31 | I29: =H31 | J29: =I31 | K29: =J31 | L29: =K31 | M29: =L31
B30: Net Cash Flow | D30: =D9+D14+D22 | E30: =E9+E14+E22 | F30: =F9+F14+F22 | G30: =G9+G14+G22 | H30: =H9+H14+H22 | I30: =I9+I14+I22 | J30: =J9+J14+J22 | K30: =K9+K14+K22 | ... M30: =M9+M14+M22
B31: Closing Cash | D31: =D29+D30 | E31: =E29+E30 | F31: =F29+F30 | G31: =G29+G30 | H31: =H29+H30 | I31: =I29+I30 | J31: =J29+J30 | K31: =K29+K30 | ... M31: =M29+M30
B32: AUDIT: CF Cash vs BS Cash (should be 0) | D32: =D31-'Balance Sheet'!D5 | E32: =E31-'Balance Sheet'!E5 | F32: =F31-'Balance Sheet'!F5 | G32: =G31-'Balance Sheet'!G5 | H32: =H31-'Balance Sheet'!H5 | I32: =I31-'Balance Sheet'!I5 | J32: =J31-'Balance Sheet'!J5 | K32: =K31-'Balance Sheet'!K5 | ... M32: =M31-'Balance Sheet'!M5

Sheet DCF Valuation
B1: DCF VALUATION (£m; mid-year convention; Gordon Growth TV)
I2: FY2025E | J2: FY2026E | K2: FY2027E | L2: FY2028E | M2: FY2029E
B4: Unlevered Free Cash Flow Build
B5: EBITDA | C5: From Income Statement | I5: ='Income Statement'!I10 | J5: ='Income Statement'!J10 | K5: ='Income Statement'!K10 | L5: ='Income Statement'!L10 | M5: ='Income Statement'!M10
B6: Less: Tax on EBIT (NOPAT adj.) | C6: EBIT x tax rate | I6: =-'Income Statement'!I15*'Assumptions'!I21 | J6: =-'Income Statement'!J15*'Assumptions'!J21 | K6: =-'Income Statement'!K15*'Assumptions'!K21 | L6: =-'Income Statement'!L15*'Assumptions'!L21 | M6: =-'Income Statement'!M15*'Assumptions'!M21
B7: Less: Capex | I7: =-'Capex & DA'!I6 | J7: =-'Capex & DA'!J6 | K7: =-'Capex & DA'!K6 | L7: =-'Capex & DA'!L6 | M7: =-'Capex & DA'!M6
B8: Less: Change in WC | I8: =-'WC Schedule'!I19 | J8: =-'WC Schedule'!J19 | K8: =-'WC Schedule'!K19 | L8: =-'WC Schedule'!L19 | M8: =-'WC Schedule'!M19
B9: Unlevered FCF | I9: =I5+I6+I7+I8 | J9: =J5+J6+J7+J8 | K9: =K5+K6+K7+K8 | L9: =L5+L6+L7+L8 | M9: =M5+M6+M7+M8
B11: Discounting (mid-year convention)
B12: WACC | C12: From Assumptions | I12: ='Assumptions'!I33 | J12: ='Assumptions'!I33 | K12: ='Assumptions'!I33 | L12: ='Assumptions'!I33 | M12: ='Assumptions'!I33
B13: Discount Period (mid-year) | C13: 0.5, 1.5, 2.5, 3.5, 4.5 | I13: 0.5 | J13: 1.5 | K13: 2.5 | L13: 3.5 | M13: 4.5
B14: Discount Factor | I14: =1/(1+I12)^I13 | J14: =1/(1+J12)^J13 | K14: =1/(1+K12)^K13 | L14: =1/(1+L12)^L13 | M14: =1/(1+M12)^M13
B15: PV of UFCF | I15: =I9*I14 | J15: =J9*J14 | K15: =K9*K14 | L15: =L9*L14 | M15: =M9*M14
B16: Sum of PV(FCF) | I16: =I15+J15+K15+L15+M15
B18: Terminal Value (Gordon Growth Model)
B19: Terminal Growth Rate | C19: From Assumptions | I19: ='Assumptions'!I36
B20: Terminal Value [UFCF5 x (1+g)/(WACC-g)] | I20: =M9*(1+I19)/(I12-I19)
B21: PV of Terminal Value | I21: =I20*M14
B23: Enterprise Value Bridge to Equity Value
B24: Enterprise Value | I24: =I16+I21
B25: Plus: Cash (FY25E) | C25: BS FY25E cash balance | I25: ='Balance Sheet'!I5
B26: Less: Gross Debt (exc leases) | C26: Debt Schedule FY25E closing | I26: =-'Debt & Interest'!I7
B27: Less: Lease Liabilities | C27: Debt Schedule FY25E closing | I27: =-'Debt & Interest'!I15
B28: Equity Value (£m) | I28: =I24+I25+I26+I27
B29: Diluted Shares (m) | C29: FY25E from Div & Buyback | I29: ='Div & Buyback'!I8
B30: Implied Share Price (pence) | I30: =I28/I29*100
B31: Current Share Price (pence) | I31: 2500
B32: Upside / (Downside) % | I32: =(I30-I31)/I31
B34: Sensitivity: Implied Share Price (p) by WACC x TGR
B35: WACC -> | C35: WACC across top; TGR down left side | I35: 0.05 | J35: 0.055 | K35: 0.062 | L35: 0.07 | M35: 0.075
B36: TGR (down) | C36: 0.015 | I36: =((I9/(1+0.05)^0.5+J9/(1+0.05)^1.5+K9/(1+0.05)^2.5+L9/(1+0.05)^3.5+M9/(1+0.05)^4.5)+((M9*(1+0.015)/(0.05-0.015))/(1+0.05)^4.5)+I25+I26+I27)/I29*100 | J36: =((I9/(1+0.055)^0.5+J9/(1+0.055)^1.5+K9/(1+0.055)^2.5+L9/(1+0.055)^3.5+M9/(1+0.055)^4.5)+((M9*(1+0.015)/(0.055-0.015))/(1+0.055)^4.5)+I25+I26+I27)/I29*100 | K36: =((I9/(1+0.062)^0.5+J9/(1+0.062)^1.5+K9/(1+0.062)^2.5+L9/(1+0.062)^3.5+M9/(1+0.062)^4.5)+((M9*(1+0.015)/(0.062-0.015))/(1+0.062)^4.5)+I25+I26+I27)/I29*100 | L36: =((I9/(1+0.07)^0.5+J9/(1+0.07)^1.5+K9/(1+0.07)^2.5+L9/(1+0.07)^3.5+M9/(1+0.07)^4.5)+((M9*(1+0.015)/(0.07-0.015))/(1+0.07)^4.5)+I25+I26+I27)/I29*100 | M36: =((I9/(1+0.075)^0.5+J9/(1+0.075)^1.5+K9/(1+0.075)^2.5+L9/(1+0.075)^3.5+M9/(1+0.075)^4.5)+((M9*(1+0.015)/(0.075-0.015))/(1+0.075)^4.5)+I25+I26+I27)/I29*100
C37: 0.02 | I37: =((I9/(1+0.05)^0.5+J9/(1+0.05)^1.5+K9/(1+0.05)^2.5+L9/(1+0.05)^3.5+M9/(1+0.05)^4.5)+((M9*(1+0.02)/(0.05-0.02))/(1+0.05)^4.5)+I25+I26+I27)/I29*100 | J37: =((I9/(1+0.055)^0.5+J9/(1+0.055)^1.5+K9/(1+0.055)^2.5+L9/(1+0.055)^3.5+M9/(1+0.055)^4.5)+((M9*(1+0.02)/(0.055-0.02))/(1+0.055)^4.5)+I25+I26+I27)/I29*100 | K37: =((I9/(1+0.062)^0.5+J9/(1+0.062)^1.5+K9/(1+0.062)^2.5+L9/(1+0.062)^3.5+M9/(1+0.062)^4.5)+((M9*(1+0.02)/(0.062-0.02))/(1+0.062)^4.5)+I25+I26+I27)/I29*100 | L37: =((I9/(1+0.07)^0.5+J9/(1+0.07)^1.5+K9/(1+0.07)^2.5+L9/(1+0.07)^3.5+M9/(1+0.07)^4.5)+((M9*(1+0.02)/(0.07-0.02))/(1+0.07)^4.5)+I25+I26+I27)/I29*100 | M37: =((I9/(1+0.075)^0.5+J9/(1+0.075)^1.5+K9/(1+0.075)^2.5+L9/(1+0.075)^3.5+M9/(1+0.075)^4.5)+((M9*(1+0.02)/(0.075-0.02))/(1+0.075)^4.5)+I25+I26+I27)/I29*100
C38: 0.025 | I38: =((I9/(1+0.05)^0.5+J9/(1+0.05)^1.5+K9/(1+0.05)^2.5+L9/(1+0.05)^3.5+M9/(1+0.05)^4.5)+((M9*(1+0.025)/(0.05-0.025))/(1+0.05)^4.5)+I25+I26+I27)/I29*100 | J38: =((I9/(1+0.055)^0.5+J9/(1+0.055)^1.5+K9/(1+0.055)^2.5+L9/(1+0.055)^3.5+M9/(1+0.055)^4.5)+((M9*(1+0.025)/(0.055-0.025))/(1+0.055)^4.5)+I25+I26+I27)/I29*100 | K38: =((I9/(1+0.062)^0.5+J9/(1+0.062)^1.5+K9/(1+0.062)^2.5+L9/(1+0.062)^3.5+M9/(1+0.062)^4.5)+((M9*(1+0.025)/(0.062-0.025))/(1+0.062)^4.5)+I25+I26+I27)/I29*100 | L38: =((I9/(1+0.07)^0.5+J9/(1+0.07)^1.5+K9/(1+0.07)^2.5+L9/(1+0.07)^3.5+M9/(1+0.07)^4.5)+((M9*(1+0.025)/(0.07-0.025))/(1+0.07)^4.5)+I25+I26+I27)/I29*100 | M38: =((I9/(1+0.075)^0.5+J9/(1+0.075)^1.5+K9/(1+0.075)^2.5+L9/(1+0.075)^3.5+M9/(1+0.075)^4.5)+((M9*(1+0.025)/(0.075-0.025))/(1+0.075)^4.5)+I25+I26+I27)/I29*100
C39: 0.03 | I39: =((I9/(1+0.05)^0.5+J9/(1+0.05)^1.5+K9/(1+0.05)^2.5+L9/(1+0.05)^3.5+M9/(1+0.05)^4.5)+((M9*(1+0.03)/(0.05-0.03))/(1+0.05)^4.5)+I25+I26+I27)/I29*100 | J39: =((I9/(1+0.055)^0.5+J9/(1+0.055)^1.5+K9/(1+0.055)^2.5+L9/(1+0.055)^3.5+M9/(1+0.055)^4.5)+((M9*(1+0.03)/(0.055-0.03))/(1+0.055)^4.5)+I25+I26+I27)/I29*100 | K39: =((I9/(1+0.062)^0.5+J9/(1+0.062)^1.5+K9/(1+0.062)^2.5+L9/(1+0.062)^3.5+M9/(1+0.062)^4.5)+((M9*(1+0.03)/(0.062-0.03))/(1+0.062)^4.5)+I25+I26+I27)/I29*100 | L39: =((I9/(1+0.07)^0.5+J9/(1+0.07)^1.5+K9/(1+0.07)^2.5+L9/(1+0.07)^3.5+M9/(1+0.07)^4.5)+((M9*(1+0.03)/(0.07-0.03))/(1+0.07)^4.5)+I25+I26+I27)/I29*100 | M39: =((I9/(1+0.075)^0.5+J9/(1+0.075)^1.5+K9/(1+0.075)^2.5+L9/(1+0.075)^3.5+M9/(1+0.075)^4.5)+((M9*(1+0.03)/(0.075-0.03))/(1+0.075)^4.5)+I25+I26+I27)/I29*100
C40: 0.035 | I40: =((I9/(1+0.05)^0.5+J9/(1+0.05)^1.5+K9/(1+0.05)^2.5+L9/(1+0.05)^3.5+M9/(1+0.05)^4.5)+((M9*(1+0.035)/(0.05-0.035))/(1+0.05)^4.5)+I25+I26+I27)/I29*100 | J40: =((I9/(1+0.055)^0.5+J9/(1+0.055)^1.5+K9/(1+0.055)^2.5+L9/(1+0.055)^3.5+M9/(1+0.055)^4.5)+((M9*(1+0.035)/(0.055-0.035))/(1+0.055)^4.5)+I25+I26+I27)/I29*100 | K40: =((I9/(1+0.062)^0.5+J9/(1+0.062)^1.5+K9/(1+0.062)^2.5+L9/(1+0.062)^3.5+M9/(1+0.062)^4.5)+((M9*(1+0.035)/(0.062-0.035))/(1+0.062)^4.5)+I25+I26+I27)/I29*100 | L40: =((I9/(1+0.07)^0.5+J9/(1+0.07)^1.5+K9/(1+0.07)^2.5+L9/(1+0.07)^3.5+M9/(1+0.07)^4.5)+((M9*(1+0.035)/(0.07-0.035))/(1+0.07)^4.5)+I25+I26+I27)/I29*100 | M40: =((I9/(1+0.075)^0.5+J9/(1+0.075)^1.5+K9/(1+0.075)^2.5+L9/(1+0.075)^3.5+M9/(1+0.075)^4.5)+((M9*(1+0.035)/(0.075-0.035))/(1+0.075)^4.5)+I25+I26+I27)/I29*100

Sheet Trading Comps
B1: TRADING COMPS — GLOBAL SPIRITS PEERS
B2: Source: FactSet consensus as of 31 March 2025 | LTM multiples, NTM P/E
B3: Company | C3: Ticker | D3: Mkt Cap (£bn) | E3: EV (£bn) | F3: Rev (£bn) | G3: EBITDA (£m) | H3: EV/EBITDA | I3: EV/Revenue | J3: P/E (fwd) | K3: Div Yield
B4: Diageo PLC | C4: DGE LN | D4: 55.8 | E4: 72.5 | F4: 15.8 | G4: 5380 | H4: 13.5 | I4: 4.59x | J4: 19.2 | K4: 3.3
B5: Pernod Ricard | C5: RI FP | D5: 32.5 | E5: 44.8 | F5: 11.6 | G5: 3420 | H5: 13.1 | I5: 3.86x | J5: 17.8 | K5: 3.8
B6: Brown-Forman | C6: BF.B US | D6: 21.2 | E6: 23.8 | F6: 4.1 | G6: 1350 | H6: 17.6 | I6: 5.80x | J6: 25.4 | K6: 1.8
B7: Remy Cointreau | C7: RCO FP | D7: 5.8 | E7: 7.2 | F7: 1.2 | G7: 310 | H7: 23.2 | I7: 6.00x | J7: 28.5 | K7: 2.5
B8: Campari | C8: CPR IM | D8: 8.6 | E8: 11.2 | F8: 2.9 | G8: 680 | H8: 16.5 | I8: 3.86x | J8: 21.8 | K8: 1.2
B9: Constellation Brands | C9: STZ US | D9: 35.4 | E9: 48.6 | F9: 9.8 | G9: 4200 | H9: 11.6 | I9: 4.96x | J9: 16.5 | K9: 1.7
B11: Peer Median | H11: 14.8 | J11: 21.8 | K11: 0.0215
B12: Peer Mean | H12: 16.4 | J12: 21.8 | K12: 0.022
B14: IMPLIED DIAGEO VALUATION FROM COMPS
B15: Diageo FY24 EBITDA (£m) | D15: 5380
B16: Peer median EV/EBITDA | D16: 14.8
B17: Implied EV (£m) | D17: =D15*D16
B18: Less: Net Debt ex-leases FY24 (£m) | D18: =-'Debt & Interest'!H26
B19: Less: Lease Liabilities FY24 (£m) | D19: =-'Debt & Interest'!H15
B20: Implied Equity Value (£m) | D20: =D17+D18+D19
B21: Diluted Shares (m) | D21: 2235
B22: Implied Price (pence) | D22: =D20/D21*100

Sheet Charts
B1: CHARTS — KEY FINANCIAL METRICS
B2: Year | D2: FY2020A | E2: FY2021A | F2: FY2022A | G2: FY2023A | H2: FY2024A | I2: FY2025E | J2: FY2026E | K2: FY2027E | L2: FY2028E | M2: FY2029E
B3: Revenue (£m) | D3: 11752 | E3: 12733 | F3: 15452 | G3: 17113 | H3: 15806 | I3: 16373 | J3: 17044 | K3: 17691 | L3: 18274 | M3: 18877
B4: EBITDA (£m) | D4: 4050 | E4: 4410 | F4: 5320 | G4: 5900 | H4: 5380 | I4: 5649 | J4: 5965 | K4: 6227 | L4: 6487 | M4: 6758
B5: EBITDA Margin | D5: 0.3446 | E5: 0.3463 | F5: 0.3443 | G5: 0.3448 | H5: 0.3404 | I5: 0.345 | J5: 0.35 | K5: 0.352 | L5: 0.355 | M5: 0.358
B6: UFCF (£m) | D6: 2799 | E6: 3207 | F6: 3777 | G6: 4071 | H6: 3546 | I6: 3745 | J6: 3966 | K6: 4155 | L6: 4340 | M6: 4534
B7: Net Debt ex-leases | D7: 10600 | E7: 11600 | F7: 13600 | G7: 14600 | H7: 14800 | I7: 14400 | J7: 14000 | K7: 13500 | L7: 13000 | M7: 12500
B8: ND/EBITDA | D8: 2.62 | E8: 2.63 | F8: 2.56 | G8: 2.47 | H8: 2.75 | I8: 2.55 | J8: 2.35 | K8: 2.17 | L8: 2 | M8: 1.85
B10: Valuation Method | C10: Low (p) | D10: Mid (p) | E10: High (p)
B11: DCF (base case) | C11: 2200 | D11: 600 | E11: 600
B12: DCF (bull) | C12: 2800 | D12: 500 | E12: 500
B13: EV/EBITDA comps | C13: 2100 | D13: 500 | E13: 500
B14: P/E comps | C14: 2300 | D14: 400 | E14: 400
B15: 52-wk range | C15: 2150 | D15: 350 | E15: 350
